Workbook

Sheet Bioenergy_Data
A1: Owner | B1: Fuel | C1: Fuel (no space after comma) | D1: Fuel 1 | E1: Fuel 2 | F1: Fuel 3 | G1: Capacity (MW) | H1: Status | I1: Start Year | J1: Retired Year | K1: Latitude | L1: Longitude | M1: Country/Area | N1: Generation (TWh) | O1: Emission Factor (kg CO2/ mmBtu) | P1: Fuel Consumption (mmBtu) | Q1: CO2 Emissions (g CO2) | R1: Carbon Intensity (g CO2/ kWh)
A2: bh energy gap llp | B2: bioenergy: refuse (municipal and industrial wastes) | C2: =SUBSTITUTE(Table1[[#This Row],[Fuel]],", ",",") -> bioenergy: refuse (municipal and industrial wastes) | D2: bioenergy: refuse (municipal and industrial wastes) | G2: 44 | H2: pre-construction | I2: 2027 | J2: N/A | K2: 52.6086 | L2: -2.0103 | M2: united kingdom | N2: =Table1[[#This Row],[Capacity (MW)]]*8760*0.72*10^-6 -> 0.2775168 | O2: {=AVERAGE(VLOOKUP(_xlfn.TEXTSPLIT(Table1[[#This Row],[Fuel (no space after comma)]], ","), FuelList_Final_EF!$A$2:$B$32, 2, FALSE))} -> 105.42963 | P2: =(16112*Table1[[#This Row],[Generation (TWh)]]*10^9)/10^6 -> 4471350.7 | Q2: =Table1[[#This Row],[Emission Factor (kg CO2/ mmBtu)]]*Table1[[#This Row],[Fuel Consumption (mmBtu)]]*10^3 -> 4.7141283e+11 | R2: =(Table1[[#This Row],[CO2 Emissions (g CO2)]])/(Table1[[#This Row],[Generation (TWh)]]*10^9) -> 1698.6821 | T2: =AVERAGE(Table1[Carbon Intensity (g CO2/ kWh)]) -> 1682.2644
A3: metsä fibre oy | B3: bioenergy: wood & other biomass (solids), bioenergy: wood & other biomass (syngas) | C3: =SUBSTITUTE(Table1[[#This Row],[Fuel]],", ",",") -> bioenergy: wood & other biomass (solids),bioenergy: wood & other biomass (syngas) | D3: bioenergy: wood & other biomass (solids) | E3: bioenergy: wood & other biomass (syngas) | G3: 260 | H3: operating | I3: 2017 | J3: N/A | K3: 62.5908 | L3: 25.7522 | M3: finland | N3: =Table1[[#This Row],[Capacity (MW)]]*8760*0.72*10^-6 -> 1.639872 | O3: {=AVERAGE(VLOOKUP(_xlfn.TEXTSPLIT(Table1[[#This Row],[Fuel (no space after comma)]], ","), FuelList_Final_EF!$A$2:$B$32, 2, FALSE))} -> 70.305377 | P3: =(16112*Table1[[#This Row],[Generation (TWh)]]*10^9)/10^6 -> 26421618 | Q3: =Table1[[#This Row],[Emission Factor (kg CO2/ mmBtu)]]*Table1[[#This Row],[Fuel Consumption (mmBtu)]]*10^3 -> 1.8575818e+12 | R3: =(Table1[[#This Row],[CO2 Emissions (g CO2)]])/(Table1[[#This Row],[Generation (TWh)]]*10^9) -> 1132.7602
A4: renergy group partners llc | B4: bioenergy: refuse (municipal and industrial wastes) | C4: =SUBSTITUTE(Table1[[#This Row],[Fuel]],", ",",") -> bioenergy: refuse (municipal and industrial wastes) | D4: bioenergy: refuse (municipal and industrial wastes) | G4: 30 | H4: pre-construction | I4: 2026 | J4: N/A | K4: 30.042122 | L4: 31.095022 | M4: egypt | N4: =Table1[[#This Row],[Capacity (MW)]]*8760*0.72*10^-6 -> 0.189216 | O4: {=AVERAGE(VLOOKUP(_xlfn.TEXTSPLIT(Table1[[#This Row],[Fuel (no space after comma)]], ","), FuelList_Final_EF!$A$2:$B$32, 2, FALSE))} -> 105.42963 | P4: =(16112*Table1[[#This Row],[Generation (TWh)]]*10^9)/10^6 -> 3048648.2 | Q4: =Table1[[#This Row],[Emission Factor (kg CO2/ mmBtu)]]*Table1[[#This Row],[Fuel Consumption (mmBtu)]]*10^3 -> 3.2141784e+11 | R4: =(Table1[[#This Row],[CO2 Emissions (g CO2)]])/(Table1[[#This Row],[Generation (TWh)]]*10^9) -> 1698.6821
A5: e.on värme sverige ab | B5: bioenergy: wood & other biomass (solids), fossil liquids: waste/other oil | C5: =SUBSTITUTE(Table1[[#This Row],[Fuel]],", ",",") -> bioenergy: wood & other biomass (solids),fossil liquids: waste/other oil | D5: bioenergy: wood & other biomass (solids) | E5: fossil liquids: waste/other oil | G5: 100 | H5: operating | I5: 1974 | J5: N/A | K5: 59.2649 | L5: 15.1772 | M5: sweden | N5: =Table1[[#This Row],[Capacity (MW)]]*8760*0.72*10^-6 -> 0.63072 | O5: {=AVERAGE(VLOOKUP(_xlfn.TEXTSPLIT(Table1[[#This Row],[Fuel (no space after comma)]], ","), FuelList_Final_EF!$A$2:$B$32, 2, FALSE))} -> 85.539958 | P5: =(16112*Table1[[#This Row],[Generation (TWh)]]*10^9)/10^6 -> 10162161 | Q5: =Table1[[#This Row],[Emission Factor (kg CO2/ mmBtu)]]*Table1[[#This Row],[Fuel Consumption (mmBtu)]]*10^3 -> 8.6927079e+11 | R5: =(Table1[[#This Row],[CO2 Emissions (g CO2)]])/(Table1[[#This Row],[Generation (TWh)]]*10^9) -> 1378.2198
A6: fri el green power spa | B6: bioenergy: biodiesel | C6: =SUBSTITUTE(Table1[[#This Row],[Fuel]],", ",",") -> bioenergy: biodiesel | D6: bioenergy: biodiesel | G6: 68 | H6: operating | I6: 2008 | J6: N/A | K6: 40.9744 | L6: 14.3766 | M6: italy | N6: =Table1[[#This Row],[Capacity (MW)]]*8760*0.72*10^-6 -> 0.4288896 | O6: {=AVERAGE(VLOOKUP(_xlfn.TEXTSPLIT(Table1[[#This Row],[Fuel (no space after comma)]], ","), FuelList_Final_EF!$A$2:$B$32, 2, FALSE))} -> 73.84 | P6: =(16112*Table1[[#This Row],[Generation (TWh)]]*10^9)/10^6 -> 6910269.2 | Q6: =Table1[[#This Row],[Emission Factor (kg CO2/ mmBtu)]]*Table1[[#This Row],[Fuel Consumption (mmBtu)]]*10^3 -> 5.1025428e+11 | R6: =(Table1[[#This Row],[CO2 Emissions (g CO2)]])/(Table1[[#This Row],[Generation (TWh)]]*10^9) -> 1189.7101
A7: a2a spa | B7: bioenergy: refuse (municipal and industrial wastes) | C7: =SUBSTITUTE(Table1[[#This Row],[Fuel]],", ",",") -> bioenergy: refuse (municipal and industrial wastes) | D7: bioenergy: refuse (municipal and industrial wastes) | G7: 36 | H7: operating | I7: 2009 | J7: N/A | K7: 40.9791 | L7: 14.3828 | M7: italy | N7: =Table1[[#This Row],[Capacity (MW)]]*8760*0.72*10^-6 -> 0.2270592 | O7: {=AVERAGE(VLOOKUP(_xlfn.TEXTSPLIT(Table1[[#This Row],[Fuel (no space after comma)]], ","), FuelList_Final_EF!$A$2:$B$32, 2, FALSE))} -> 105.42963 | P7: =(16112*Table1[[#This Row],[Generation (TWh)]]*10^9)/10^6 -> 3658377.8 | Q7: =Table1[[#This Row],[Emission Factor (kg CO2/ mmBtu)]]*Table1[[#This Row],[Fuel Consumption (mmBtu)]]*10^3 -> 3.8570141e+11 | R7: =(Table1[[#This Row],[CO2 Emissions (g CO2)]])/(Table1[[#This Row],[Generation (TWh)]]*10^9) -> 1698.6821
A8: a2a spa | B8: bioenergy: refuse (municipal and industrial wastes) | C8: =SUBSTITUTE(Table1[[#This Row],[Fuel]],", ",",") -> bioenergy: refuse (municipal and industrial wastes) | D8: bioenergy: refuse (municipal and industrial wastes) | G8: 36 | H8: operating | I8: 2009 | J8: N/A | K8: 40.9791 | L8: 14.3828 | M8: italy | N8: =Table1[[#This Row],[Capacity (MW)]]*8760*0.72*10^-6 -> 0.2270592 | O8: {=AVERAGE(VLOOKUP(_xlfn.TEXTSPLIT(Table1[[#This Row],[Fuel (no space after comma)]], ","), FuelList_Final_EF!$A$2:$B$32, 2, FALSE))} -> 105.42963 | P8: =(16112*Table1[[#This Row],[Generation (TWh)]]*10^9)/10^6 -> 3658377.8 | Q8: =Table1[[#This Row],[Emission Factor (kg CO2/ mmBtu)]]*Table1[[#This Row],[Fuel Consumption (mmBtu)]]*10^3 -> 3.8570141e+11 | R8: =(Table1[[#This Row],[CO2 Emissions (g CO2)]])/(Table1[[#This Row],[Generation (TWh)]]*10^9) -> 1698.6821
A9: a2a spa | B9: bioenergy: refuse (municipal and industrial wastes) | C9: =SUBSTITUTE(Table1[[#This Row],[Fuel]],", ",",") -> bioenergy: refuse (municipal and industrial wastes) | D9: bioenergy: refuse (municipal and industrial wastes) | G9: 36 | H9: operating | I9: 2009 | J9: N/A | K9: 40.9791 | L9: 14.3828 | M9: italy | N9: =Table1[[#This Row],[Capacity (MW)]]*8760*0.72*10^-6 -> 0.2270592 | O9: {=AVERAGE(VLOOKUP(_xlfn.TEXTSPLIT(Table1[[#This Row],[Fuel (no space after comma)]], ","), FuelList_Final_EF!$A$2:$B$32, 2, FALSE))} -> 105.42963 | P9: =(16112*Table1[[#This Row],[Generation (TWh)]]*10^9)/10^6 -> 3658377.8 | Q9: =Table1[[#This Row],[Emission Factor (kg CO2/ mmBtu)]]*Table1[[#This Row],[Fuel Consumption (mmBtu)]]*10^3 -> 3.8570141e+11 | R9: =(Table1[[#This Row],[CO2 Emissions (g CO2)]])/(Table1[[#This Row],[Generation (TWh)]]*10^9) -> 1698.6821
A10: N/A | B10: bioenergy: refuse (municipal and industrial wastes) | C10: =SUBSTITUTE(Table1[[#This Row],[Fuel]],", ",",") -> bioenergy: refuse (municipal and industrial wastes) | D10: bioenergy: refuse (municipal and industrial wastes) | G10: 125 | H10: operating | I10: 1997 | J10: N/A | K10: 51.683 | L10: 4.5805 | M10: netherlands | N10: =Table1[[#This Row],[Capacity (MW)]]*8760*0.72*10^-6 -> 0.7884 | O10: {=AVERAGE(VLOOKUP(_xlfn.TEXTSPLIT(Table1[[#This Row],[Fuel (no space after comma)]], ","), FuelList_Final_EF!$A$2:$B$32, 2, FALSE))} -> 105.42963 | P10: =(16112*Table1[[#This Row],[Generation (TWh)]]*10^9)/10^6 -> 12702701 | Q10: =Table1[[#This Row],[Emission Factor (kg CO2/ mmBtu)]]*Table1[[#This Row],[Fuel Consumption (mmBtu)]]*10^3 -> 1.339241e+12 | R10: =(Table1[[#This Row],[CO2 Emissions (g CO2)]])/(Table1[[#This Row],[Generation (TWh)]]*10^9) -> 1698.6821
A11: aeb exploitatie bv | B11: bioenergy: refuse (municipal and industrial wastes), bioenergy: wastewater and sewage sludge (solids or biogas) | C11: =SUBSTITUTE(Table1[[#This Row],[Fuel]],", ",",") -> bioenergy: refuse (municipal and industrial wastes),bioenergy: wastewater and sewage sludge (solids or biogas) | D11: bioenergy: refuse (municipal and industrial wastes) | E11: bioenergy: wastewater and sewage sludge (solids or biogas) | G11: 39 | H11: operating | I11: 1993 | J11: N/A | K11: 52.4011 | L11: 4.7935 | M11: netherlands | N11: =Table1[[#This Row],[Capacity (MW)]]*8760*0.72*10^-6 -> 0.2459808 | O11: {=AVERAGE(VLOOKUP(_xlfn.TEXTSPLIT(Table1[[#This Row],[Fuel (no space after comma)]], ","), FuelList_Final_EF!$A$2:$B$32, 2, FALSE))} -> 81.497101 | P11: =(16112*Table1[[#This Row],[Generation (TWh)]]*10^9)/10^6 -> 3963242.6 | Q11: =Table1[[#This Row],[Emission Factor (kg CO2/ mmBtu)]]*Table1[[#This Row],[Fuel Consumption (mmBtu)]]*10^3 -> 3.2299279e+11 | R11: =(Table1[[#This Row],[CO2 Emissions (g CO2)]])/(Table1[[#This Row],[Generation (TWh)]]*10^9) -> 1313.0813
A12: aeb exploitatie bv | B12: bioenergy: refuse (municipal and industrial wastes), bioenergy: wastewater and sewage sludge (solids or biogas) | C12: =SUBSTITUTE(Table1[[#This Row],[Fuel]],", ",",") -> bioenergy: refuse (municipal and industrial wastes),bioenergy: wastewater and sewage sludge (solids or biogas) | D12: bioenergy: refuse (municipal and industrial wastes) | E12: bioenergy: wastewater and sewage sludge (solids or biogas) | G12: 72 | H12: operating | I12: 2007 | J12: N/A | K12: 52.4011 | L12: 4.7935 | M12: netherlands | N12: =Table1[[#This Row],[Capacity (MW)]]*8760*0.72*10^-6 -> 0.4541184 | O12: {=AVERAGE(VLOOKUP(_xlfn.TEXTSPLIT(Table1[[#This Row],[Fuel (no space after comma)]], ","), FuelList_Final_EF!$A$2:$B$32, 2, FALSE))} -> 81.497101 | P12: =(16112*Table1[[#This Row],[Generation (TWh)]]*10^9)/10^6 -> 7316755.7 | Q12: =Table1[[#This Row],[Emission Factor (kg CO2/ mmBtu)]]*Table1[[#This Row],[Fuel Consumption (mmBtu)]]*10^3 -> 5.9629437e+11 | R12: =(Table1[[#This Row],[CO2 Emissions (g CO2)]])/(Table1[[#This Row],[Generation (TWh)]]*10^9) -> 1313.0813
A13: N/A | B13: bioenergy: agricultural waste (biogas) | C13: =SUBSTITUTE(Table1[[#This Row],[Fuel]],", ",",") -> bioenergy: agricultural waste (biogas) | D13: bioenergy: agricultural waste (biogas) | G13: 1058 | H13: operating | I13: 2017 | J13: N/A | K13: -2.7165 | L13: 101.3702 | M13: indonesia | N13: =Table1[[#This Row],[Capacity (MW)]]*8760*0.72*10^-6 -> 6.6730176 | O13: {=AVERAGE(VLOOKUP(_xlfn.TEXTSPLIT(Table1[[#This Row],[Fuel (no space after comma)]], ","), FuelList_Final_EF!$A$2:$B$32, 2, FALSE))} -> 52.07 | P13: =(16112*Table1[[#This Row],[Generation (TWh)]]*10^9)/10^6 -> 1.0751566e+08 | Q13: =Table1[[#This Row],[Emission Factor (kg CO2/ mmBtu)]]*Table1[[#This Row],[Fuel Consumption (mmBtu)]]*10^3 -> 5.5983404e+12 | R13: =(Table1[[#This Row],[CO2 Emissions (g CO2)]])/(Table1[[#This Row],[Generation (TWh)]]*10^9) -> 838.95184
A14: agroaurora sac | B14: bioenergy: agricultural waste (solids) | C14: =SUBSTITUTE(Table1[[#This Row],[Fuel]],", ",",") -> bioenergy: agricultural waste (solids) | D14: bioenergy: agricultural waste (solids) | G14: 38 | H14: operating | I14: 2012 | J14: N/A | K14: -4.9279 | L14: -80.8491 | M14: peru | N14: =Table1[[#This Row],[Capacity (MW)]]*8760*0.72*10^-6 -> 0.2396736 | O14: {=AVERAGE(VLOOKUP(_xlfn.TEXTSPLIT(Table1[[#This Row],[Fuel (no space after comma)]], ","), FuelList_Final_EF!$A$2:$B$32, 2, FALSE))} -> 118.17 | P14: =(16112*Table1[[#This Row],[Generation (TWh)]]*10^9)/10^6 -> 3861621 | Q14: =Table1[[#This Row],[Emission Factor (kg CO2/ mmBtu)]]*Table1[[#This Row],[Fuel Consumption (mmBtu)]]*10^3 -> 4.5632776e+11 | R14: =(Table1[[#This Row],[CO2 Emissions (g CO2)]])/(Table1[[#This Row],[Generation (TWh)]]*10^9) -> 1903.955
A15: agropéu agro industrial de pompéu sa | B15: bioenergy: agricultural waste (solids) | C15: =SUBSTITUTE(Table1[[#This Row],[Fuel]],", ",",") -> bioenergy: agricultural waste (solids) | D15: bioenergy: agricultural waste (solids) | G15: 52 | H15: operating | I15: 2016 | J15: N/A | K15: -19.2517 | L15: -44.985 | M15: brazil | N15: =Table1[[#This Row],[Capacity (MW)]]*8760*0.72*10^-6 -> 0.3279744 | O15: {=AVERAGE(VLOOKUP(_xlfn.TEXTSPLIT(Table1[[#This Row],[Fuel (no space after comma)]], ","), FuelList_Final_EF!$A$2:$B$32, 2, FALSE))} -> 118.17 | P15: =(16112*Table1[[#This Row],[Generation (TWh)]]*10^9)/10^6 -> 5284323.5 | Q15: =Table1[[#This Row],[Emission Factor (kg CO2/ mmBtu)]]*Table1[[#This Row],[Fuel Consumption (mmBtu)]]*10^3 -> 6.2444851e+11 | R15: =(Table1[[#This Row],[CO2 Emissions (g CO2)]])/(Table1[[#This Row],[Generation (TWh)]]*10^9) -> 1903.955
A16: the aichi gamagori biomass power generation llc | B16: bioenergy: wood & other biomass (solids) | C16: =SUBSTITUTE(Table1[[#This Row],[Fuel]],", ",",") -> bioenergy: wood & other biomass (solids) | D16: bioenergy: wood & other biomass (solids) | G16: 50 | H16: operating | I16: 2023 | J16: N/A | K16: 34.8052 | L16: 137.208 | M16: japan | N16: =Table1[[#This Row],[Capacity (MW)]]*8760*0.72*10^-6 -> 0.31536 | O16: {=AVERAGE(VLOOKUP(_xlfn.TEXTSPLIT(Table1[[#This Row],[Fuel (no space after comma)]], ","), FuelList_Final_EF!$A$2:$B$32, 2, FALSE))} -> 93.8 | P16: =(16112*Table1[[#This Row],[Generation (TWh)]]*10^9)/10^6 -> 5081080.3 | Q16: =Table1[[#This Row],[Emission Factor (kg CO2/ mmBtu)]]*Table1[[#This Row],[Fuel Consumption (mmBtu)]]*10^3 -> 4.7660533e+11 | R16: =(Table1[[#This Row],[CO2 Emissions (g CO2)]])/(Table1[[#This Row],[Generation (TWh)]]*10^9) -> 1511.3056
A17: osaka gas co ltd | B17: bioenergy: wood & other biomass (solids) | C17: =SUBSTITUTE(Table1[[#This Row],[Fuel]],", ",",") -> bioenergy: wood & other biomass (solids) | D17: bioenergy: wood & other biomass (solids) | G17: 18.75 | H17: construction | I17: 2024 | J17: N/A | K17: 34.7004 | L17: 137.249 | M17: japan | N17: =Table1[[#This Row],[Capacity (MW)]]*8760*0.72*10^-6 -> 0.11826 | O17: {=AVERAGE(VLOOKUP(_xlfn.TEXTSPLIT(Table1[[#This Row],[Fuel (no space after comma)]], ","), FuelList_Final_EF!$A$2:$B$32, 2, FALSE))} -> 93.8 | P17: =(16112*Table1[[#This Row],[Generation (TWh)]]*10^9)/10^6 -> 1905405.1 | Q17: =Table1[[#This Row],[Emission Factor (kg CO2/ mmBtu)]]*Table1[[#This Row],[Fuel Consumption (mmBtu)]]*10^3 -> 178727000256 | R17: =(Table1[[#This Row],[CO2 Emissions (g CO2)]])/(Table1[[#This Row],[Generation (TWh)]]*10^9) -> 1511.3056
A18: other | B18: bioenergy: wood & other biomass (solids) | C18: =SUBSTITUTE(Table1[[#This Row],[Fuel]],", ",",") -> bioenergy: wood & other biomass (solids) | D18: bioenergy: wood & other biomass (solids) | G18: 56.25 | H18: construction | I18: 2024 | J18: N/A | K18: 34.7004 | L18: 137.249 | M18: japan | N18: =Table1[[#This Row],[Capacity (MW)]]*8760*0.72*10^-6 -> 0.35478 | O18: {=AVERAGE(VLOOKUP(_xlfn.TEXTSPLIT(Table1[[#This Row],[Fuel (no space after comma)]], ","), FuelList_Final_EF!$A$2:$B$32, 2, FALSE))} -> 93.8 | P18: =(16112*Table1[[#This Row],[Generation (TWh)]]*10^9)/10^6 -> 5716215.4 | Q18: =Table1[[#This Row],[Emission Factor (kg CO2/ mmBtu)]]*Table1[[#This Row],[Fuel Consumption (mmBtu)]]*10^3 -> 536181000768 | R18: =(Table1[[#This Row],[CO2 Emissions (g CO2)]])/(Table1[[#This Row],[Generation (TWh)]]*10^9) -> 1511.3056
A19: kansai electric power co | B19: bioenergy: wood & other biomass (solids) | C19: =SUBSTITUTE(Table1[[#This Row],[Fuel]],", ",",") -> bioenergy: wood & other biomass (solids) | D19: bioenergy: wood & other biomass (solids) | G19: 200 | H19: operating | I19: 1982 | J19: N/A | K19: 34.774809 | L19: 134.45725 | M19: japan | N19: =Table1[[#This Row],[Capacity (MW)]]*8760*0.72*10^-6 -> 1.26144 | O19: {=AVERAGE(VLOOKUP(_xlfn.TEXTSPLIT(Table1[[#This Row],[Fuel (no space after comma)]], ","), FuelList_Final_EF!$A$2:$B$32, 2, FALSE))} -> 93.8 | P19: =(16112*Table1[[#This Row],[Generation (TWh)]]*10^9)/10^6 -> 20324321 | Q19: =Table1[[#This Row],[Emission Factor (kg CO2/ mmBtu)]]*Table1[[#This Row],[Fuel Consumption (mmBtu)]]*10^3 -> 1.9064213e+12 | R19: =(Table1[[#This Row],[CO2 Emissions (g CO2)]])/(Table1[[#This Row],[Generation (TWh)]]*10^9) -> 1511.3056
A20: alternative generating company 1 llc | B20: bioenergy: refuse (municipal and industrial wastes) | C20: =SUBSTITUTE(Table1[[#This Row],[Fuel]],", ",",") -> bioenergy: refuse (municipal and industrial wastes) | D20: bioenergy: refuse (municipal and industrial wastes) | G20: 70 | H20: construction | I20: 2024 | J20: N/A | K20: 55.676358 | L20: 38.241705 | M20: russia | N20: =Table1[[#This Row],[Capacity (MW)]]*8760*0.72*10^-6 -> 0.441504 | O20: {=AVERAGE(VLOOKUP(_xlfn.TEXTSPLIT(Table1[[#This Row],[Fuel (no space after comma)]], ","), FuelList_Final_EF!$A$2:$B$32, 2, FALSE))} -> 105.42963 | P20: =(16112*Table1[[#This Row],[Generation (TWh)]]*10^9)/10^6 -> 7113512.4 | Q20: =Table1[[#This Row],[Emission Factor (kg CO2/ mmBtu)]]*Table1[[#This Row],[Fuel Consumption (mmBtu)]]*10^3 -> 7.4997495e+11 | R20: =(Table1[[#This Row],[CO2 Emissions (g CO2)]])/(Table1[[#This Row],[Generation (TWh)]]*10^9) -> 1698.6821
A21: other | B21: bioenergy: refuse (municipal and industrial wastes) | C21: =SUBSTITUTE(Table1[[#This Row],[Fuel]],", ",",") -> bioenergy: refuse (municipal and industrial wastes) | D21: bioenergy: refuse (municipal and industrial wastes) | G21: 80 | H21: pre-construction | I21: N/A | J21: N/A | K21: 24.0293 | L21: 54.3973 | M21: united arab emirates | N21: =Table1[[#This Row],[Capacity (MW)]]*8760*0.72*10^-6 -> 0.504576 | O21: {=AVERAGE(VLOOKUP(_xlfn.TEXTSPLIT(Table1[[#This Row],[Fuel (no space after comma)]], ","), FuelList_Final_EF!$A$2:$B$32, 2, FALSE))} -> 105.42963 | P21: =(16112*Table1[[#This Row],[Generation (TWh)]]*10^9)/10^6 -> 8129728.5 | Q21: =Table1[[#This Row],[Emission Factor (kg CO2/ mmBtu)]]*Table1[[#This Row],[Fuel Consumption (mmBtu)]]*10^3 -> 8.5711423e+11 | R21: =(Table1[[#This Row],[CO2 Emissions (g CO2)]])/(Table1[[#This Row],[Generation (TWh)]]*10^9) -> 1698.6821
A22: alabama river cellulose llc | B22: bioenergy: paper mill wastes, bioenergy: wood & other biomass (solids) | C22: =SUBSTITUTE(Table1[[#This Row],[Fuel]],", ",",") -> bioenergy: paper mill wastes,bioenergy: wood & other biomass (solids) | D22: bioenergy: paper mill wastes | E22: bioenergy: wood & other biomass (solids) | G22: 69 | H22: operating | I22: 1991 | J22: N/A | K22: 31.5825 | L22: -87.4889 | M22: united states | N22: =Table1[[#This Row],[Capacity (MW)]]*8760*0.72*10^-6 -> 0.4351968 | O22: {=AVERAGE(VLOOKUP(_xlfn.TEXTSPLIT(Table1[[#This Row],[Fuel (no space after comma)]], ","), FuelList_Final_EF!$A$2:$B$32, 2, FALSE))} -> 97.137217 | P22: =(16112*Table1[[#This Row],[Generation (TWh)]]*10^9)/10^6 -> 7011890.8 | Q22: =Table1[[#This Row],[Emission Factor (kg CO2/ mmBtu)]]*Table1[[#This Row],[Fuel Consumption (mmBtu)]]*10^3 -> 6.8111556e+11 | R22: =(Table1[[#This Row],[CO2 Emissions (g CO2)]])/(Table1[[#This Row],[Generation (TWh)]]*10^9) -> 1565.0748
A23: alabama river cellulose llc | B23: bioenergy: paper mill wastes, bioenergy: wood & other biomass (solids) | C23: =SUBSTITUTE(Table1[[#This Row],[Fuel]],", ",",") -> bioenergy: paper mill wastes,bioenergy: wood & other biomass (solids) | D23: bioenergy: paper mill wastes | E23: bioenergy: wood & other biomass (solids) | G23: 48 | H23: operating | I23: 1978 | J23: N/A | K23: 31.5825 | L23: -87.4889 | M23: united states | N23: =Table1[[#This Row],[Capacity (MW)]]*8760*0.72*10^-6 -> 0.3027456 | O23: {=AVERAGE(VLOOKUP(_xlfn.TEXTSPLIT(Table1[[#This Row],[Fuel (no space after comma)]], ","), FuelList_Final_EF!$A$2:$B$32, 2, FALSE))} -> 97.137217 | P23: =(16112*Table1[[#This Row],[Generation (TWh)]]*10^9)/10^6 -> 4877837.1 | Q23: =Table1[[#This Row],[Emission Factor (kg CO2/ mmBtu)]]*Table1[[#This Row],[Fuel Consumption (mmBtu)]]*10^3 -> 4.7381952e+11 | R23: =(Table1[[#This Row],[CO2 Emissions (g CO2)]])/(Table1[[#This Row],[Generation (TWh)]]*10^9) -> 1565.0748
A24: nsl sugars ltd | B24: bioenergy: agricultural waste (solids), coal: unknown | C24: =SUBSTITUTE(Table1[[#This Row],[Fuel]],", ",",") -> bioenergy: agricultural waste (solids),coal: unknown | D24: bioenergy: agricultural waste (solids) | E24: coal: unknown | G24: 34 | H24: operating | I24: 2012 | J24: N/A | K24: 17.4622 | L24: 76.5651 | M24: india | N24: =Table1[[#This Row],[Capacity (MW)]]*8760*0.72*10^-6 -> 0.2144448 | O24: {=AVERAGE(VLOOKUP(_xlfn.TEXTSPLIT(Table1[[#This Row],[Fuel (no space after comma)]], ","), FuelList_Final_EF!$A$2:$B$32, 2, FALSE))} -> 109.63851 | P24: =(16112*Table1[[#This Row],[Generation (TWh)]]*10^9)/10^6 -> 3455134.6 | Q24: =Table1[[#This Row],[Emission Factor (kg CO2/ mmBtu)]]*Table1[[#This Row],[Fuel Consumption (mmBtu)]]*10^3 -> 3.788158e+11 | R24: =(Table1[[#This Row],[CO2 Emissions (g CO2)]])/(Table1[[#This Row],[Generation (TWh)]]*10^9) -> 1766.4956
A25: regenerate energy holdings llc | B25: bioenergy: wood & other biomass (solids), fossil gas: natural gas | C25: =SUBSTITUTE(Table1[[#This Row],[Fuel]],", ",",") -> bioenergy: wood & other biomass (solids),fossil gas: natural gas | D25: bioenergy: wood & other biomass (solids) | E25: fossil gas: natural gas | G25: 55 | H25: operating | I25: 2017 | J25: N/A | K25: 31.5559 | L25: -84.1103 | M25: united states | N25: =Table1[[#This Row],[Capacity (MW)]]*8760*0.72*10^-6 -> 0.346896 | O25: {=AVERAGE(VLOOKUP(_xlfn.TEXTSPLIT(Table1[[#This Row],[Fuel (no space after comma)]], ","), FuelList_Final_EF!$A$2:$B$32, 2, FALSE))} -> 73.43 | P25: =(16112*Table1[[#This Row],[Generation (TWh)]]*10^9)/10^6 -> 5589188.4 | Q25: =Table1[[#This Row],[Emission Factor (kg CO2/ mmBtu)]]*Table1[[#This Row],[Fuel Consumption (mmBtu)]]*10^3 -> 4.104141e+11 | R25: =(Table1[[#This Row],[CO2 Emissions (g CO2)]])/(Table1[[#This Row],[Generation (TWh)]]*10^9) -> 1183.1042
A26: green power cagayan philippines inc | B26: bioenergy: wood & other biomass (solids) | C26: =SUBSTITUTE(Table1[[#This Row],[Fuel]],", ",",") -> bioenergy: wood & other biomass (solids) | D26: bioenergy: wood & other biomass (solids) | G26: 30 | H26: cancelled | I26: N/A | J26: N/A | K26: 17.9405 | L26: 121.6818 | M26: philippines | N26: =Table1[[#This Row],[Capacity (MW)]]*8760*0.72*10^-6 -> 0.189216 | O26: {=AVERAGE(VLOOKUP(_xlfn.TEXTSPLIT(Table1[[#This Row],[Fuel (no space after comma)]], ","), FuelList_Final_EF!$A$2:$B$32, 2, FALSE))} -> 93.8 | P26: =(16112*Table1[[#This Row],[Generation (TWh)]]*10^9)/10^6 -> 3048648.2 | Q26: =Table1[[#This Row],[Emission Factor (kg CO2/ mmBtu)]]*Table1[[#This Row],[Fuel Consumption (mmBtu)]]*10^3 -> 2.859632e+11 | R26: =(Table1[[#This Row],[CO2 Emissions (g CO2)]])/(Table1[[#This Row],[Generation (TWh)]]*10^9) -> 1511.3056
A27: atvos bioenergia alcidia sa | B27: bioenergy: agricultural waste (solids) | C27: =SUBSTITUTE(Table1[[#This Row],[Fuel]],", ",",") -> bioenergy: agricultural waste (solids) | D27: bioenergy: agricultural waste (solids) | G27: 38 | H27: operating | I27: 2010 | J27: N/A | K27: -22.3497 | L27: -52.524 | M27: brazil | N27: =Table1[[#This Row],[Capacity (MW)]]*8760*0.72*10^-6 -> 0.2396736 | O27: {=AVERAGE(VLOOKUP(_xlfn.TEXTSPLIT(Table1[[#This Row],[Fuel (no space after comma)]], ","), FuelList_Final_EF!$A$2:$B$32, 2, FALSE))} -> 118.17 | P27: =(16112*Table1[[#This Row],[Generation (TWh)]]*10^9)/10^6 -> 3861621 | Q27: =Table1[[#This Row],[Emission Factor (kg CO2/ mmBtu)]]*Table1[[#This Row],[Fuel Consumption (mmBtu)]]*10^3 -> 4.5632776e+11 | R27: =(Table1[[#This Row],[CO2 Emissions (g CO2)]])/(Table1[[#This Row],[Generation (TWh)]]*10^9) -> 1903.955
A28: alcogroup sa | B28: bioenergy: agricultural waste (unknown) | C28: =SUBSTITUTE(Table1[[#This Row],[Fuel]],", ",",") -> bioenergy: agricultural waste (unknown) | D28: bioenergy: agricultural waste (unknown) | G28: 60 | H28: operating | I28: 2010 | J28: N/A | K28: 51.9248 | L28: 4.1815 | M28: netherlands | N28: =Table1[[#This Row],[Capacity (MW)]]*8760*0.72*10^-6 -> 0.378432 | O28: {=AVERAGE(VLOOKUP(_xlfn.TEXTSPLIT(Table1[[#This Row],[Fuel (no space after comma)]], ","), FuelList_Final_EF!$A$2:$B$32, 2, FALSE))} -> 72.350251 | P28: =(16112*Table1[[#This Row],[Generation (TWh)]]*10^9)/10^6 -> 6097296.4 | Q28: =Table1[[#This Row],[Emission Factor (kg CO2/ mmBtu)]]*Table1[[#This Row],[Fuel Consumption (mmBtu)]]*10^3 -> 4.4114093e+11 | R28: =(Table1[[#This Row],[CO2 Emissions (g CO2)]])/(Table1[[#This Row],[Generation (TWh)]]*10^9) -> 1165.7072
A29: companhia de álcool conceição da barra sa | B29: bioenergy: agricultural waste (solids) | C29: =SUBSTITUTE(Table1[[#This Row],[Fuel]],", ",",") -> bioenergy: agricultural waste (solids) | D29: bioenergy: agricultural waste (solids) | G29: 33 | H29: operating | I29: 2001 | J29: N/A | K29: -18.4574 | L29: -39.9454 | M29: brazil | N29: =Table1[[#This Row],[Capacity (MW)]]*8760*0.72*10^-6 -> 0.2081376 | O29: {=AVERAGE(VLOOKUP(_xlfn.TEXTSPLIT(Table1[[#This Row],[Fuel (no space after comma)]], ","), FuelList_Final_EF!$A$2:$B$32, 2, FALSE))} -> 118.17 | P29: =(16112*Table1[[#This Row],[Generation (TWh)]]*10^9)/10^6 -> 3353513 | Q29: =Table1[[#This Row],[Emission Factor (kg CO2/ mmBtu)]]*Table1[[#This Row],[Fuel Consumption (mmBtu)]]*10^3 -> 3.9628463e+11 | R29: =(Table1[[#This Row],[CO2 Emissions (g CO2)]])/(Table1[[#This Row],[Generation (TWh)]]*10^9) -> 1903.955
A30: fcc environment | B30: bioenergy: refuse (municipal and industrial wastes) | C30: =SUBSTITUTE(Table1[[#This Row],[Fuel]],", ",",") -> bioenergy: refuse (municipal and industrial wastes) | D30: bioenergy: refuse (municipal and industrial wastes) | G30: 43 | H30: operating | I30: 2008 | J30: N/A | K30: 51.2931 | L30: 0.4924 | M30: united kingdom | N30: =Table1[[#This Row],[Capacity (MW)]]*8760*0.72*10^-6 -> 0.2712096 | O30: {=AVERAGE(VLOOKUP(_xlfn.TEXTSPLIT(Table1[[#This Row],[Fuel (no space after comma)]], ","), FuelList_Final_EF!$A$2:$B$32, 2, FALSE))} -> 105.42963 | P30: =(16112*Table1[[#This Row],[Generation (TWh)]]*10^9)/10^6 -> 4369729.1 | Q30: =Table1[[#This Row],[Emission Factor (kg CO2/ mmBtu)]]*Table1[[#This Row],[Fuel Consumption (mmBtu)]]*10^3 -> 4.606989e+11 | R30: =(Table1[[#This Row],[CO2 Emissions (g CO2)]])/(Table1[[#This Row],[Generation (TWh)]]*10^9) -> 1698.6821
A31: alberta pacific forest industries inc | B31: bioenergy: paper mill wastes | C31: =SUBSTITUTE(Table1[[#This Row],[Fuel]],", ",",") -> bioenergy: paper mill wastes | D31: bioenergy: paper mill wastes | G31: 41 | H31: operating | I31: 1993 | J31: N/A | K31: 54.921 | L31: -112.8622 | M31: canada | N31: =Table1[[#This Row],[Capacity (MW)]]*8760*0.72*10^-6 -> 0.2585952 | O31: {=AVERAGE(VLOOKUP(_xlfn.TEXTSPLIT(Table1[[#This Row],[Fuel (no space after comma)]], ","), FuelList_Final_EF!$A$2:$B$32, 2, FALSE))} -> 100.47443 | P31: =(16112*Table1[[#This Row],[Generation (TWh)]]*10^9)/10^6 -> 4166485.9 | Q31: =Table1[[#This Row],[Emission Factor (kg CO2/ mmBtu)]]*Table1[[#This Row],[Fuel Consumption (mmBtu)]]*10^3 -> 4.1862531e+11 | R31: =(Table1[[#This Row],[CO2 Emissions (g CO2)]])/(Table1[[#This Row],[Generation (TWh)]]*10^9) -> 1618.8441
A32: alberta pacific forest industries inc | B32: bioenergy: paper mill wastes | C32: =SUBSTITUTE(Table1[[#This Row],[Fuel]],", ",",") -> bioenergy: paper mill wastes | D32: bioenergy: paper mill wastes | G32: 41 | H32: operating | I32: 1993 | J32: N/A | K32: 54.921 | L32: -112.8622 | M32: canada | N32: =Table1[[#This Row],[Capacity (MW)]]*8760*0.72*10^-6 -> 0.2585952 | O32: {=AVERAGE(VLOOKUP(_xlfn.TEXTSPLIT(Table1[[#This Row],[Fuel (no space after comma)]], ","), FuelList_Final_EF!$A$2:$B$32, 2, FALSE))} -> 100.47443 | P32: =(16112*Table1[[#This Row],[Generation (TWh)]]*10^9)/10^6 -> 4166485.9 | Q32: =Table1[[#This Row],[Emission Factor (kg CO2/ mmBtu)]]*Table1[[#This Row],[Fuel Consumption (mmBtu)]]*10^3 -> 4.1862531e+11 | R32: =(Table1[[#This Row],[CO2 Emissions (g CO2)]])/(Table1[[#This Row],[Generation (TWh)]]*10^9) -> 1618.8441
A33: usina alta mogiana sa | B33: bioenergy: agricultural waste (solids) | C33: =SUBSTITUTE(Table1[[#This Row],[Fuel]],", ",",") -> bioenergy: agricultural waste (solids) | D33: bioenergy: agricultural waste (solids) | G33: 71 | H33: operating | I33: 1994 | J33: N/A | K33: -20.4818 | L33: -47.8662 | M33: brazil | N33: =Table1[[#This Row],[Capacity (MW)]]*8760*0.72*10^-6 -> 0.4478112 | O33: {=AVERAGE(VLOOKUP(_xlfn.TEXTSPLIT(Table1[[#This Row],[Fuel (no space after comma)]], ","), FuelList_Final_EF!$A$2:$B$32, 2, FALSE))} -> 118.17 | P33: =(16112*Table1[[#This Row],[Generation (TWh)]]*10^9)/10^6 -> 7215134.1 | Q33: =Table1[[#This Row],[Emission Factor (kg CO2/ mmBtu)]]*Table1[[#This Row],[Fuel Consumption (mmBtu)]]*10^3 -> 8.5261239e+11 | R33: =(Table1[[#This Row],[CO2 Emissions (g CO2)]])/(Table1[[#This Row],[Generation (TWh)]]*10^9) -> 1903.955
A34: virginia electric and power co | B34: bioenergy: wood & other biomass (solids), fossil gas: natural gas | C34: =SUBSTITUTE(Table1[[#This Row],[Fuel]],", ",",") -> bioenergy: wood & other biomass (solids),fossil gas: natural gas | D34: bioenergy: wood & other biomass (solids) | E34: fossil gas: natural gas | G34: 71 | H34: operating | I34: 1992 | J34: N/A | K34: 37.118481 | L34: -79.273027 | M34: united states | N34: =Table1[[#This Row],[Capacity (MW)]]*8760*0.72*10^-6 -> 0.4478112 | O34: {=AVERAGE(VLOOKUP(_xlfn.TEXTSPLIT(Table1[[#This Row],[Fuel (no space after comma)]], ","), FuelList_Final_EF!$A$2:$B$32, 2, FALSE))} -> 73.43 | P34: =(16112*Table1[[#This Row],[Generation (TWh)]]*10^9)/10^6 -> 7215134.1 | Q34: =Table1[[#This Row],[Emission Factor (kg CO2/ mmBtu)]]*Table1[[#This Row],[Fuel Consumption (mmBtu)]]*10^3 -> 5.2980729e+11 | R34: =(Table1[[#This Row],[CO2 Emissions (g CO2)]])/(Table1[[#This Row],[Generation (TWh)]]*10^9) -> 1183.1042
A35: i/s amager resourcecenter | B35: bioenergy: refuse (municipal and industrial wastes) | C35: =SUBSTITUTE(Table1[[#This Row],[Fuel]],", ",",") -> bioenergy: refuse (municipal and industrial wastes) | D35: bioenergy: refuse (municipal and industrial wastes) | G35: 63 | H35: operating | I35: 2019 | J35: N/A | K35: 55.6842 | L35: 12.6193 | M35: denmark | N35: =Table1[[#This Row],[Capacity (MW)]]*8760*0.72*10^-6 -> 0.3973536 | O35: {=AVERAGE(VLOOKUP(_xlfn.TEXTSPLIT(Table1[[#This Row],[Fuel (no space after comma)]], ","), FuelList_Final_EF!$A$2:$B$32, 2, FALSE))} -> 105.42963 | P35: =(16112*Table1[[#This Row],[Generation (TWh)]]*10^9)/10^6 -> 6402161.2 | Q35: =Table1[[#This Row],[Emission Factor (kg CO2/ mmBtu)]]*Table1[[#This Row],[Fuel Consumption (mmBtu)]]*10^3 -> 6.7497746e+11 | R35: =(Table1[[#This Row],[CO2 Emissions (g CO2)]])/(Table1[[#This Row],[Generation (TWh)]]*10^9) -> 1698.6821
A36: hofor a/s | B36: bioenergy: wood & other biomass (solids) | C36: =SUBSTITUTE(Table1[[#This Row],[Fuel]],", ",",") -> bioenergy: wood & other biomass (solids) | D36: bioenergy: wood & other biomass (solids) | G36: 68 | H36: operating | I36: 1971 | J36: N/A | K36: 55.686777 | L36: 12.627702 | M36: denmark | N36: =Table1[[#This Row],[Capacity (MW)]]*8760*0.72*10^-6 -> 0.4288896 | O36: {=AVERAGE(VLOOKUP(_xlfn.TEXTSPLIT(Table1[[#This Row],[Fuel (no space after comma)]], ","), FuelList_Final_EF!$A$2:$B$32, 2, FALSE))} -> 93.8 | P36: =(16112*Table1[[#This Row],[Generation (TWh)]]*10^9)/10^6 -> 6910269.2 | Q36: =Table1[[#This Row],[Emission Factor (kg CO2/ mmBtu)]]*Table1[[#This Row],[Fuel Consumption (mmBtu)]]*10^3 -> 6.4818325e+11 | R36: =(Table1[[#This Row],[CO2 Emissions (g CO2)]])/(Table1[[#This Row],[Generation (TWh)]]*10^9) -> 1511.3056
A37: hofor a/s | B37: bioenergy: wood & other biomass (solids) | C37: =SUBSTITUTE(Table1[[#This Row],[Fuel]],", ",",") -> bioenergy: wood & other biomass (solids) | D37: bioenergy: wood & other biomass (solids) | G37: 150 | H37: operating | I37: 2020 | J37: N/A | K37: 55.686777 | L37: 12.627702 | M37: denmark | N37: =Table1[[#This Row],[Capacity (MW)]]*8760*0.72*10^-6 -> 0.94608 | O37: {=AVERAGE(VLOOKUP(_xlfn.TEXTSPLIT(Table1[[#This Row],[Fuel (no space after comma)]], ","), FuelList_Final_EF!$A$2:$B$32, 2, FALSE))} -> 93.8 | P37: =(16112*Table1[[#This Row],[Generation (TWh)]]*10^9)/10^6 -> 15243241 | Q37: =Table1[[#This Row],[Emission Factor (kg CO2/ mmBtu)]]*Table1[[#This Row],[Fuel Consumption (mmBtu)]]*10^3 -> 1429816002048 | R37: =(Table1[[#This Row],[CO2 Emissions (g CO2)]])/(Table1[[#This Row],[Generation (TWh)]]*10^9) -> 1511.3056
A38: brazil adecoagro participações sa | B38: bioenergy: agricultural waste (solids) | C38: =SUBSTITUTE(Table1[[#This Row],[Fuel]],", ",",") -> bioenergy: agricultural waste (solids) | D38: bioenergy: agricultural waste (solids) | G38: 40 | H38: operating | I38: 2018 | J38: N/A | K38: -22.3251 | L38: -53.8212 | M38: brazil | N38: =Table1[[#This Row],[Capacity (MW)]]*8760*0.72*10^-6 -> 0.252288 | O38: {=AVERAGE(VLOOKUP(_xlfn.TEXTSPLIT(Table1[[#This Row],[Fuel (no space after comma)]], ","), FuelList_Final_EF!$A$2:$B$32, 2, FALSE))} -> 118.17 | P38: =(16112*Table1[[#This Row],[Generation (TWh)]]*10^9)/10^6 -> 4064864.3 | Q38: =Table1[[#This Row],[Emission Factor (kg CO2/ mmBtu)]]*Table1[[#This Row],[Fuel Consumption (mmBtu)]]*10^3 -> 4.8034501e+11 | R38: =(Table1[[#This Row],[CO2 Emissions (g CO2)]])/(Table1[[#This Row],[Generation (TWh)]]*10^9) -> 1903.955
A39: ivinhema energia ltda | B39: bioenergy: agricultural waste (solids) | C39: =SUBSTITUTE(Table1[[#This Row],[Fuel]],", ",",") -> bioenergy: agricultural waste (solids) | D39: bioenergy: agricultural waste (solids) | G39: 40 | H39: pre-construction | I39: N/A | J39: N/A | K39: -22.3956 | L39: -53.8904 | M39: brazil | N39: =Table1[[#This Row],[Capacity (MW)]]*8760*0.72*10^-6 -> 0.252288 | O39: {=AVERAGE(VLOOKUP(_xlfn.TEXTSPLIT(Table1[[#This Row],[Fuel (no space after comma)]], ","), FuelList_Final_EF!$A$2:$B$32, 2, FALSE))} -> 118.17 | P39: =(16112*Table1[[#This Row],[Generation (TWh)]]*10^9)/10^6 -> 4064864.3 | Q39: =Table1[[#This Row],[Emission Factor (kg CO2/ mmBtu)]]*Table1[[#This Row],[Fuel Consumption (mmBtu)]]*10^3 -> 4.8034501e+11 | R39: =(Table1[[#This Row],[CO2 Emissions (g CO2)]])/(Table1[[#This Row],[Generation (TWh)]]*10^9) -> 1903.955
A40: adecoagro vale do ivinhema sa | B40: bioenergy: agricultural waste (solids) | C40: =SUBSTITUTE(Table1[[#This Row],[Fuel]],", ",",") -> bioenergy: agricultural waste (solids) | D40: bioenergy: agricultural waste (solids) | G40: 40 | H40: operating | I40: 2014 | J40: N/A | K40: -22.4381 | L40: -53.5781 | M40: brazil | N40: =Table1[[#This Row],[Capacity (MW)]]*8760*0.72*10^-6 -> 0.252288 | O40: {=AVERAGE(VLOOKUP(_xlfn.TEXTSPLIT(Table1[[#This Row],[Fuel (no space after comma)]], ","), FuelList_Final_EF!$A$2:$B$32, 2, FALSE))} -> 118.17 | P40: =(16112*Table1[[#This Row],[Generation (TWh)]]*10^9)/10^6 -> 4064864.3 | Q40: =Table1[[#This Row],[Emission Factor (kg CO2/ mmBtu)]]*Table1[[#This Row],[Fuel Consumption (mmBtu)]]*10^3 -> 4.8034501e+11 | R40: =(Table1[[#This Row],[CO2 Emissions (g CO2)]])/(Table1[[#This Row],[Generation (TWh)]]*10^9) -> 1903.955
...

Sheet FuelList_Final_EF
A1: Fuel | B1: Emission Factor (kg CO2/ mmBtu) | C1: Source | D1: Comment
A2: {=_xlfn.UNIQUE(FuelList_IntermediateStep!A2:A58)} -> bioenergy: refuse (municipal and industrial wastes) | B2: =100000/948.5 -> 105.42963 | C2: https://www.ipcc-nggip.iges.or.jp/public/2006gl/pdf/2_Volume2/V2_2_Ch2_Stationary_Combustion.pdf | D2: Municipal wastes biomass-fraction
A3: bioenergy: wood & other biomass (solids) | B3: 93.8 | C3: https://www.epa.gov/system/files/documents/2025-01/ghg-emission-factors-hub-2025.pdf
A4: bioenergy: biodiesel | B4: 73.84 | C4: https://www.epa.gov/system/files/documents/2025-01/ghg-emission-factors-hub-2025.pdf
A5: bioenergy: agricultural waste (biogas) | B5: 52.07 | C5: https://www.epa.gov/system/files/documents/2025-01/ghg-emission-factors-hub-2025.pdf
A6: bioenergy: agricultural waste (solids) | B6: 118.17 | C6: https://www.epa.gov/system/files/documents/2025-01/ghg-emission-factors-hub-2025.pdf
A7: bioenergy: paper mill wastes | B7: =95300/948.5 -> 100.47443 | C7: https://www.ipcc-nggip.iges.or.jp/public/2006gl/pdf/2_Volume2/V2_2_Ch2_Stationary_Combustion.pdf
A8: bioenergy: agricultural waste (unknown) | B8: =AVERAGE(B5,B6,B13) -> 72.350251 | C8: Average of "bioenergy: agricultural waste"
A9: bioenergy: unknown | B9: =AVERAGE(B2,B3,B4,B5,B6,B7,B10,B11,B12,B13,B14,B15,B17) -> 72.785606 | C9: Average of "bioenergy:"
A10: bioenergy: refuse (syngas) | B10: =44400/948.5 -> 46.810754 | C10: https://www.ipcc-nggip.iges.or.jp/public/2006gl/pdf/2_Volume2/V2_2_Ch2_Stationary_Combustion.pdf | D10: Gas works gas
A11: bioenergy: refuse (landfill gas) | B11: 52.07 | C11: https://www.epa.gov/system/files/documents/2025-01/ghg-emission-factors-hub-2025.pdf
A12: bioenergy: wastewater and sewage sludge (solids or biogas) | B12: =54600/948.5 -> 57.564576 | C12: https://www.ipcc-nggip.iges.or.jp/public/2006gl/pdf/2_Volume2/V2_2_Ch2_Stationary_Combustion.pdf | D12: Sewage gas
A13: bioenergy: agricultural waste (syngas) | B13: =44400/948.5 -> 46.810754 | C13: https://www.ipcc-nggip.iges.or.jp/public/2006gl/pdf/2_Volume2/V2_2_Ch2_Stationary_Combustion.pdf | D13: Gas works gas
A14: bioenergy: wood & other biomass (biocoal) | B14: =79600/948.5 -> 83.921982 | C14: https://www.ipcc-nggip.iges.or.jp/public/2006gl/pdf/2_Volume2/V2_2_Ch2_Stationary_Combustion.pdf | D14: Other liquid biofuels
A15: bioenergy: ethanol | B15: 68.44 | C15: https://www.epa.gov/system/files/documents/2025-01/ghg-emission-factors-hub-2025.pdf
A16: 0
A17: bioenergy: wood & other biomass (syngas) | B17: =44400/948.5 -> 46.810754 | C17: https://www.ipcc-nggip.iges.or.jp/public/2006gl/pdf/2_Volume2/V2_2_Ch2_Stationary_Combustion.pdf | D17: Gas works gas
A18: fossil liquids: waste/other oil | B18: =73300/948.5 -> 77.279916 | C18: https://www.ipcc-nggip.iges.or.jp/public/2006gl/pdf/2_Volume2/V2_2_Ch2_Stationary_Combustion.pdf
A19: coal: unknown | B19: =AVERAGE(B21,B23,B28,B29) -> 101.10701 | C19: Average of "coal:"
A20: fossil gas: natural gas | B20: 53.06 | C20: https://www.epa.gov/system/files/documents/2025-01/ghg-emission-factors-hub-2025.pdf
A21: coal: bituminous | B21: =94600/948.5 -> 99.736426 | C21: https://www.ipcc-nggip.iges.or.jp/public/2006gl/pdf/2_Volume2/V2_2_Ch2_Stationary_Combustion.pdf
A22: fossil liquids: heavy fuel oil | B22: =77400/948.5 -> 81.60253 | C22: https://www.sciencedirect.com/topics/engineering/specific-emission-factor
A23: coal: subbituminous | B23: =96100/948.5 -> 101.31787 | C23: https://www.ipcc-nggip.iges.or.jp/public/2006gl/pdf/2_Volume2/V2_2_Ch2_Stationary_Combustion.pdf
A24: other: other | B24: =AVERAGE(B32) -> 85.97 | C24: Average of "other:"
A25: fossil liquids: petroleum coke | B25: 102.41 | C25: https://www.epa.gov/system/files/documents/2025-01/ghg-emission-factors-hub-2025.pdf
A26: fossil liquids: unknown | B26: =AVERAGE(B18,B22,B25,B27) -> 84.849782 | C26: Average of "fossil liquids:"
A27: fossil liquids: fuel oil | B27: =0.2665/0.003412 -> 78.106682 | C27: https://www.volker-quaschning.de/datserv/CO2-spez/index_e.php
A28: coal: anthracite | B28: =98300/948.5 -> 103.63732 | C28: https://www.ipcc-nggip.iges.or.jp/public/2006gl/pdf/2_Volume2/V2_2_Ch2_Stationary_Combustion.pdf
A29: coal: waste coal | B29: =94600/948.5 -> 99.736426 | C29: https://www.ipcc-nggip.iges.or.jp/public/2006gl/pdf/2_Volume2/V2_2_Ch2_Stationary_Combustion.pdf
A30: fossil gas: unknown | B30: =AVERAGE(B20,B31) -> 60.37291 | C30: Average of "fossil gas:"
A31: fossil gas: lng | B31: =64200/948.5 -> 67.68582 | C31: https://www.ipcc-nggip.iges.or.jp/public/2006gl/pdf/2_Volume2/V2_2_Ch2_Stationary_Combustion.pdf
A32: other: tires | B32: 85.97 | C32: https://www.ipcc-nggip.iges.or.jp/public/2006gl/pdf/2_Volume2/V2_2_Ch2_Stationary_Combustion.pdf

Sheet FuelList_IntermediateStep
A1: Fuel: Intermediate Step
A2: {=_xlfn.UNIQUE(Bioenergy_Data!D2:D2837)} -> bioenergy: refuse (municipal and industrial wastes)
A3: bioenergy: wood & other biomass (solids)
A4: bioenergy: biodiesel
A5: bioenergy: agricultural waste (biogas)
A6: bioenergy: agricultural waste (solids)
A7: bioenergy: paper mill wastes
A8: bioenergy: agricultural waste (unknown)
A9: bioenergy: unknown
A10: bioenergy: refuse (syngas)
A11: bioenergy: refuse (landfill gas)
A12: bioenergy: wastewater and sewage sludge (solids or biogas)
A13: bioenergy: agricultural waste (syngas)
A14: bioenergy: wood & other biomass (biocoal)
A15: bioenergy: ethanol
A16: {=_xlfn.UNIQUE(Bioenergy_Data!E2:E2837)} -> 0
A17: bioenergy: wood & other biomass (syngas)
A18: fossil liquids: waste/other oil
A19: bioenergy: wastewater and sewage sludge (solids or biogas)
A20: bioenergy: wood & other biomass (solids)
A21: coal: unknown
A22: fossil gas: natural gas
A23: coal: bituminous
A24: fossil liquids: heavy fuel oil
A25: coal: subbituminous
A26: bioenergy: refuse (municipal and industrial wastes)
A27: bioenergy: agricultural waste (solids)
A28: other: other
... A38: bioenergy: refuse (landfill gas)
A39: {=_xlfn.UNIQUE(Bioenergy_Data!F2:F2837)} -> 0
A40: bioenergy: wastewater and sewage sludge (solids or biogas)
A41: fossil gas: natural gas
A42: fossil liquids: heavy fuel oil
A43: coal: unknown
A44: fossil liquids: unknown
A45: fossil gas: unknown
A46: coal: bituminous
A47: other: other
A48: fossil liquids: waste/other oil
A49: bioenergy: wood & other biomass (solids)
...
