Workbook

Sheet Gas_Oil_Data
A1: Owner | B1: Fuel | C1: Fuel (no space after comma) | D1: Fuel 1 | E1: Fuel 2 | F1: Fuel 3 | G1: Fuel 4 | H1: Turbine/Engine Technology | I1: Capacity (MW) | J1: Status | K1: Start Year | L1: Retired Year | M1: Planned retire | N1: Latitude | O1: Longitude | P1: Country/Area | Q1: Generation (TWh) | R1: Emission Factor (kg CO2/ mmBtu) | S1: Fuel Consumption (mmBtu) | T1: Emissions (g CO2) | U1: Carbon Intensity (g CO2/ kWh)
A2: bayat power electricity services distributor co | B2: fossil gas: natural gas | C2: =SUBSTITUTE(Table1[[#This Row],[Fuel]],", ",",") -> fossil gas: natural gas | D2: fossil gas: natural gas | H2: gas turbine | I2: 80 | J2: shelved - inferred 2 y | K2: N/A | L2: N/A | M2: N/A | N2: 36.692494 | O2: 65.985089 | P2: afghanistan | Q2: =Table1[[#This Row],[Capacity (MW)]]*0.395*8760*10^-6 -> 0.276816 | R2: {=AVERAGE(VLOOKUP(_xlfn.TEXTSPLIT(Table1[[#This Row],[Fuel (no space after comma)]], ","), FuelList_Final_EF!$A$2:$B$65, 2, FALSE))} -> 53.06 | S2: =Table1[[#This Row],[Generation (TWh)]]*10^9*VLOOKUP(Table1[[#This Row],[Turbine/Engine Technology]],Technology_HR!$A$2:$B$11,2,FALSE)*10^-6 -> 3047744.2 | T2: =Table1[[#This Row],[Fuel Consumption (mmBtu)]]*Table1[[#This Row],[Emission Factor (kg CO2/ mmBtu)]]*10^3 -> 1.6171331e+11 | U2: =Table1[[#This Row],[Emissions (g CO2)]]/(Table1[[#This Row],[Generation (TWh)]]*10^9) -> 584.1906
A3: bayat power electricity services distributor co | B3: fossil gas: natural gas | C3: =SUBSTITUTE(Table1[[#This Row],[Fuel]],", ",",") -> fossil gas: natural gas | D3: fossil gas: natural gas | H3: gas turbine | I3: 80 | J3: shelved - inferred 2 y | K3: N/A | L3: N/A | M3: N/A | N3: 36.692494 | O3: 65.985089 | P3: afghanistan | Q3: =Table1[[#This Row],[Capacity (MW)]]*0.395*8760*10^-6 -> 0.276816 | R3: {=AVERAGE(VLOOKUP(_xlfn.TEXTSPLIT(Table1[[#This Row],[Fuel (no space after comma)]], ","), FuelList_Final_EF!$A$2:$B$65, 2, FALSE))} -> 53.06 | S3: =Table1[[#This Row],[Generation (TWh)]]*10^9*VLOOKUP(Table1[[#This Row],[Turbine/Engine Technology]],Technology_HR!$A$2:$B$11,2,FALSE)*10^-6 -> 3047744.2 | T3: =Table1[[#This Row],[Fuel Consumption (mmBtu)]]*Table1[[#This Row],[Emission Factor (kg CO2/ mmBtu)]]*10^3 -> 1.6171331e+11 | U3: =Table1[[#This Row],[Emissions (g CO2)]]/(Table1[[#This Row],[Generation (TWh)]]*10^9) -> 584.1906
A4: ghazanfar group llc | B4: fossil gas: natural gas | C4: =SUBSTITUTE(Table1[[#This Row],[Fuel]],", ",",") -> fossil gas: natural gas | D4: fossil gas: natural gas | H4: internal combustion | I4: 59 | J4: shelved | K4: N/A | L4: N/A | M4: N/A | N4: 36.7032 | O4: 67.13556 | P4: afghanistan | Q4: =Table1[[#This Row],[Capacity (MW)]]*0.395*8760*10^-6 -> 0.2041518 | R4: {=AVERAGE(VLOOKUP(_xlfn.TEXTSPLIT(Table1[[#This Row],[Fuel (no space after comma)]], ","), FuelList_Final_EF!$A$2:$B$65, 2, FALSE))} -> 53.06 | S4: =Table1[[#This Row],[Generation (TWh)]]*10^9*VLOOKUP(Table1[[#This Row],[Turbine/Engine Technology]],Technology_HR!$A$2:$B$11,2,FALSE)*10^-6 -> 1816951 | T4: =Table1[[#This Row],[Fuel Consumption (mmBtu)]]*Table1[[#This Row],[Emission Factor (kg CO2/ mmBtu)]]*10^3 -> 9.6407421e+10 | U4: =Table1[[#This Row],[Emissions (g CO2)]]/(Table1[[#This Row],[Generation (TWh)]]*10^9) -> 472.234
A5: united states agency for international development | B5: fossil gas: natural gas, fossil liquids: diesel | C5: =SUBSTITUTE(Table1[[#This Row],[Fuel]],", ",",") -> fossil gas: natural gas,fossil liquids: diesel | D5: fossil gas: natural gas | E5: fossil liquids: diesel | H5: internal combustion | I5: 105 | J5: operating | K5: 2009 | L5: N/A | M5: N/A | N5: 34.561557 | O5: 69.294854 | P5: afghanistan | Q5: =Table1[[#This Row],[Capacity (MW)]]*0.395*8760*10^-6 -> 0.363321 | R5: {=AVERAGE(VLOOKUP(_xlfn.TEXTSPLIT(Table1[[#This Row],[Fuel (no space after comma)]], ","), FuelList_Final_EF!$A$2:$B$65, 2, FALSE))} -> 65.583341 | S5: =Table1[[#This Row],[Generation (TWh)]]*10^9*VLOOKUP(Table1[[#This Row],[Turbine/Engine Technology]],Technology_HR!$A$2:$B$11,2,FALSE)*10^-6 -> 3233556.9 | T5: =Table1[[#This Row],[Fuel Consumption (mmBtu)]]*Table1[[#This Row],[Emission Factor (kg CO2/ mmBtu)]]*10^3 -> 2.1206747e+11 | U5: =Table1[[#This Row],[Emissions (g CO2)]]/(Table1[[#This Row],[Generation (TWh)]]*10^9) -> 583.69174
A6: fier thermoelectric | B6: fossil gas: natural gas | C6: =SUBSTITUTE(Table1[[#This Row],[Fuel]],", ",",") -> fossil gas: natural gas | D6: fossil gas: natural gas | H6: combined cycle | I6: 170 | J6: pre-construction | K6: N/A | L6: N/A | M6: N/A | N6: 40.737819 | O6: 19.703411 | P6: albania | Q6: =Table1[[#This Row],[Capacity (MW)]]*0.395*8760*10^-6 -> 0.588234 | R6: {=AVERAGE(VLOOKUP(_xlfn.TEXTSPLIT(Table1[[#This Row],[Fuel (no space after comma)]], ","), FuelList_Final_EF!$A$2:$B$65, 2, FALSE))} -> 53.06 | S6: =Table1[[#This Row],[Generation (TWh)]]*10^9*VLOOKUP(Table1[[#This Row],[Turbine/Engine Technology]],Technology_HR!$A$2:$B$11,2,FALSE)*10^-6 -> 4440578.5 | T6: =Table1[[#This Row],[Fuel Consumption (mmBtu)]]*Table1[[#This Row],[Emission Factor (kg CO2/ mmBtu)]]*10^3 -> 2.3561709e+11 | U6: =Table1[[#This Row],[Emissions (g CO2)]]/(Table1[[#This Row],[Generation (TWh)]]*10^9) -> 400.54994
A7: excelerate energy lp | B7: fossil liquids: heavy fuel oil | C7: =SUBSTITUTE(Table1[[#This Row],[Fuel]],", ",",") -> fossil liquids: heavy fuel oil | D7: fossil liquids: heavy fuel oil | H7: internal combustion | I7: 52.2 | J7: mothballed | K7: 2023 | L7: N/A | M7: N/A | N7: 40.473319 | O7: 19.445376 | P7: albania | Q7: =Table1[[#This Row],[Capacity (MW)]]*0.395*8760*10^-6 -> 0.18062244 | R7: {=AVERAGE(VLOOKUP(_xlfn.TEXTSPLIT(Table1[[#This Row],[Fuel (no space after comma)]], ","), FuelList_Final_EF!$A$2:$B$65, 2, FALSE))} -> 81.60253 | S7: =Table1[[#This Row],[Generation (TWh)]]*10^9*VLOOKUP(Table1[[#This Row],[Turbine/Engine Technology]],Technology_HR!$A$2:$B$11,2,FALSE)*10^-6 -> 1607539.7 | T7: =Table1[[#This Row],[Fuel Consumption (mmBtu)]]*Table1[[#This Row],[Emission Factor (kg CO2/ mmBtu)]]*10^3 -> 1.3117931e+11 | U7: =Table1[[#This Row],[Emissions (g CO2)]]/(Table1[[#This Row],[Generation (TWh)]]*10^9) -> 726.26252
A8: excelerate energy lp | B8: fossil liquids: heavy fuel oil | C8: =SUBSTITUTE(Table1[[#This Row],[Fuel]],", ",",") -> fossil liquids: heavy fuel oil | D8: fossil liquids: heavy fuel oil | H8: internal combustion | I8: 58 | J8: mothballed | K8: 2023 | L8: N/A | M8: N/A | N8: 40.473319 | O8: 19.445376 | P8: albania | Q8: =Table1[[#This Row],[Capacity (MW)]]*0.395*8760*10^-6 -> 0.2006916 | R8: {=AVERAGE(VLOOKUP(_xlfn.TEXTSPLIT(Table1[[#This Row],[Fuel (no space after comma)]], ","), FuelList_Final_EF!$A$2:$B$65, 2, FALSE))} -> 81.60253 | S8: =Table1[[#This Row],[Generation (TWh)]]*10^9*VLOOKUP(Table1[[#This Row],[Turbine/Engine Technology]],Technology_HR!$A$2:$B$11,2,FALSE)*10^-6 -> 1786155.2 | T8: =Table1[[#This Row],[Fuel Consumption (mmBtu)]]*Table1[[#This Row],[Emission Factor (kg CO2/ mmBtu)]]*10^3 -> 1.4575479e+11 | U8: =Table1[[#This Row],[Emissions (g CO2)]]/(Table1[[#This Row],[Generation (TWh)]]*10^9) -> 726.26252
A9: korporata elektroenergjitike shqiptare sha | B9: fossil gas: lng | C9: =SUBSTITUTE(Table1[[#This Row],[Fuel]],", ",",") -> fossil gas: lng | D9: fossil gas: lng | H9: unknown | I9: 100 | J9: pre-construction | K9: N/A | L9: N/A | M9: N/A | N9: 40.490183 | O9: 19.435491 | P9: albania | Q9: =Table1[[#This Row],[Capacity (MW)]]*0.395*8760*10^-6 -> 0.34602 | R9: {=AVERAGE(VLOOKUP(_xlfn.TEXTSPLIT(Table1[[#This Row],[Fuel (no space after comma)]], ","), FuelList_Final_EF!$A$2:$B$65, 2, FALSE))} -> 67.68582 | S9: =Table1[[#This Row],[Generation (TWh)]]*10^9*VLOOKUP(Table1[[#This Row],[Turbine/Engine Technology]],Technology_HR!$A$2:$B$11,2,FALSE)*10^-6 -> 2870408.9 | T9: =Table1[[#This Row],[Fuel Consumption (mmBtu)]]*Table1[[#This Row],[Emission Factor (kg CO2/ mmBtu)]]*10^3 -> 1.9428598e+11 | U9: =Table1[[#This Row],[Emissions (g CO2)]]/(Table1[[#This Row],[Generation (TWh)]]*10^9) -> 561.48772
A10: korporata elektroenergjitike shqiptare sha | B10: fossil gas: lng | C10: =SUBSTITUTE(Table1[[#This Row],[Fuel]],", ",",") -> fossil gas: lng | D10: fossil gas: lng | H10: unknown | I10: 150 | J10: pre-construction | K10: N/A | L10: N/A | M10: N/A | N10: 40.490183 | O10: 19.435491 | P10: albania | Q10: =Table1[[#This Row],[Capacity (MW)]]*0.395*8760*10^-6 -> 0.51903 | R10: {=AVERAGE(VLOOKUP(_xlfn.TEXTSPLIT(Table1[[#This Row],[Fuel (no space after comma)]], ","), FuelList_Final_EF!$A$2:$B$65, 2, FALSE))} -> 67.68582 | S10: =Table1[[#This Row],[Generation (TWh)]]*10^9*VLOOKUP(Table1[[#This Row],[Turbine/Engine Technology]],Technology_HR!$A$2:$B$11,2,FALSE)*10^-6 -> 4305613.4 | T10: =Table1[[#This Row],[Fuel Consumption (mmBtu)]]*Table1[[#This Row],[Emission Factor (kg CO2/ mmBtu)]]*10^3 -> 2.9142897e+11 | U10: =Table1[[#This Row],[Emissions (g CO2)]]/(Table1[[#This Row],[Generation (TWh)]]*10^9) -> 561.48772
A11: korporata elektroenergjitike shqiptare sha | B11: fossil gas: lng | C11: =SUBSTITUTE(Table1[[#This Row],[Fuel]],", ",",") -> fossil gas: lng | D11: fossil gas: lng | H11: unknown | I11: 100 | J11: pre-construction | K11: N/A | L11: N/A | M11: N/A | N11: 40.490183 | O11: 19.435491 | P11: albania | Q11: =Table1[[#This Row],[Capacity (MW)]]*0.395*8760*10^-6 -> 0.34602 | R11: {=AVERAGE(VLOOKUP(_xlfn.TEXTSPLIT(Table1[[#This Row],[Fuel (no space after comma)]], ","), FuelList_Final_EF!$A$2:$B$65, 2, FALSE))} -> 67.68582 | S11: =Table1[[#This Row],[Generation (TWh)]]*10^9*VLOOKUP(Table1[[#This Row],[Turbine/Engine Technology]],Technology_HR!$A$2:$B$11,2,FALSE)*10^-6 -> 2870408.9 | T11: =Table1[[#This Row],[Fuel Consumption (mmBtu)]]*Table1[[#This Row],[Emission Factor (kg CO2/ mmBtu)]]*10^3 -> 1.9428598e+11 | U11: =Table1[[#This Row],[Emissions (g CO2)]]/(Table1[[#This Row],[Generation (TWh)]]*10^9) -> 561.48772
A12: société algérienne de production de l'electricité spa | B12: fossil gas: natural gas, fossil liquids: diesel | C12: =SUBSTITUTE(Table1[[#This Row],[Fuel]],", ",",") -> fossil gas: natural gas,fossil liquids: diesel | D12: fossil gas: natural gas | E12: fossil liquids: diesel | H12: combined cycle | I12: 338 | J12: operating | K12: 2019 | L12: N/A | M12: N/A | N12: 36.157607 | O12: 5.206548 | P12: algeria | Q12: =Table1[[#This Row],[Capacity (MW)]]*0.395*8760*10^-6 -> 1.1695476 | R12: {=AVERAGE(VLOOKUP(_xlfn.TEXTSPLIT(Table1[[#This Row],[Fuel (no space after comma)]], ","), FuelList_Final_EF!$A$2:$B$65, 2, FALSE))} -> 65.583341 | S12: =Table1[[#This Row],[Generation (TWh)]]*10^9*VLOOKUP(Table1[[#This Row],[Turbine/Engine Technology]],Technology_HR!$A$2:$B$11,2,FALSE)*10^-6 -> 8828914.8 | T12: =Table1[[#This Row],[Fuel Consumption (mmBtu)]]*Table1[[#This Row],[Emission Factor (kg CO2/ mmBtu)]]*10^3 -> 5.7902973e+11 | U12: =Table1[[#This Row],[Emissions (g CO2)]]/(Table1[[#This Row],[Generation (TWh)]]*10^9) -> 495.08864
A13: société algérienne de production de l'electricité spa | B13: fossil gas: natural gas, fossil liquids: diesel | C13: =SUBSTITUTE(Table1[[#This Row],[Fuel]],", ",",") -> fossil gas: natural gas,fossil liquids: diesel | D13: fossil gas: natural gas | E13: fossil liquids: diesel | H13: combined cycle | I13: 338 | J13: operating | K13: 2019 | L13: N/A | M13: N/A | N13: 36.157607 | O13: 5.206548 | P13: algeria | Q13: =Table1[[#This Row],[Capacity (MW)]]*0.395*8760*10^-6 -> 1.1695476 | R13: {=AVERAGE(VLOOKUP(_xlfn.TEXTSPLIT(Table1[[#This Row],[Fuel (no space after comma)]], ","), FuelList_Final_EF!$A$2:$B$65, 2, FALSE))} -> 65.583341 | S13: =Table1[[#This Row],[Generation (TWh)]]*10^9*VLOOKUP(Table1[[#This Row],[Turbine/Engine Technology]],Technology_HR!$A$2:$B$11,2,FALSE)*10^-6 -> 8828914.8 | T13: =Table1[[#This Row],[Fuel Consumption (mmBtu)]]*Table1[[#This Row],[Emission Factor (kg CO2/ mmBtu)]]*10^3 -> 5.7902973e+11 | U13: =Table1[[#This Row],[Emissions (g CO2)]]/(Table1[[#This Row],[Generation (TWh)]]*10^9) -> 495.08864
A14: société algérienne de production de l'electricité spa | B14: fossil gas: natural gas, fossil liquids: diesel | C14: =SUBSTITUTE(Table1[[#This Row],[Fuel]],", ",",") -> fossil gas: natural gas,fossil liquids: diesel | D14: fossil gas: natural gas | E14: fossil liquids: diesel | H14: combined cycle | I14: 338 | J14: operating | K14: 2019 | L14: N/A | M14: N/A | N14: 36.157607 | O14: 5.206548 | P14: algeria | Q14: =Table1[[#This Row],[Capacity (MW)]]*0.395*8760*10^-6 -> 1.1695476 | R14: {=AVERAGE(VLOOKUP(_xlfn.TEXTSPLIT(Table1[[#This Row],[Fuel (no space after comma)]], ","), FuelList_Final_EF!$A$2:$B$65, 2, FALSE))} -> 65.583341 | S14: =Table1[[#This Row],[Generation (TWh)]]*10^9*VLOOKUP(Table1[[#This Row],[Turbine/Engine Technology]],Technology_HR!$A$2:$B$11,2,FALSE)*10^-6 -> 8828914.8 | T14: =Table1[[#This Row],[Fuel Consumption (mmBtu)]]*Table1[[#This Row],[Emission Factor (kg CO2/ mmBtu)]]*10^3 -> 5.7902973e+11 | U14: =Table1[[#This Row],[Emissions (g CO2)]]/(Table1[[#This Row],[Generation (TWh)]]*10^9) -> 495.08864
A15: société algérienne de production de l'electricité spa | B15: fossil gas: natural gas, fossil liquids: fuel oil | C15: =SUBSTITUTE(Table1[[#This Row],[Fuel]],", ",",") -> fossil gas: natural gas,fossil liquids: fuel oil | D15: fossil gas: natural gas | E15: fossil liquids: fuel oil | H15: gas turbine | I15: 126 | J15: operating | K15: 2010 | L15: N/A | M15: N/A | N15: 35.8678 | O15: 6.025637 | P15: algeria | Q15: =Table1[[#This Row],[Capacity (MW)]]*0.395*8760*10^-6 -> 0.4359852 | R15: {=AVERAGE(VLOOKUP(_xlfn.TEXTSPLIT(Table1[[#This Row],[Fuel (no space after comma)]], ","), FuelList_Final_EF!$A$2:$B$65, 2, FALSE))} -> 65.583341 | S15: =Table1[[#This Row],[Generation (TWh)]]*10^9*VLOOKUP(Table1[[#This Row],[Turbine/Engine Technology]],Technology_HR!$A$2:$B$11,2,FALSE)*10^-6 -> 4800197.1 | T15: =Table1[[#This Row],[Fuel Consumption (mmBtu)]]*Table1[[#This Row],[Emission Factor (kg CO2/ mmBtu)]]*10^3 -> 3.1481296e+11 | U15: =Table1[[#This Row],[Emissions (g CO2)]]/(Table1[[#This Row],[Generation (TWh)]]*10^9) -> 722.07259
A16: société algérienne de production de l'electricité spa | B16: fossil gas: natural gas, fossil liquids: fuel oil | C16: =SUBSTITUTE(Table1[[#This Row],[Fuel]],", ",",") -> fossil gas: natural gas,fossil liquids: fuel oil | D16: fossil gas: natural gas | E16: fossil liquids: fuel oil | H16: gas turbine | I16: 126 | J16: operating | K16: 2010 | L16: N/A | M16: N/A | N16: 35.8678 | O16: 6.025637 | P16: algeria | Q16: =Table1[[#This Row],[Capacity (MW)]]*0.395*8760*10^-6 -> 0.4359852 | R16: {=AVERAGE(VLOOKUP(_xlfn.TEXTSPLIT(Table1[[#This Row],[Fuel (no space after comma)]], ","), FuelList_Final_EF!$A$2:$B$65, 2, FALSE))} -> 65.583341 | S16: =Table1[[#This Row],[Generation (TWh)]]*10^9*VLOOKUP(Table1[[#This Row],[Turbine/Engine Technology]],Technology_HR!$A$2:$B$11,2,FALSE)*10^-6 -> 4800197.1 | T16: =Table1[[#This Row],[Fuel Consumption (mmBtu)]]*Table1[[#This Row],[Emission Factor (kg CO2/ mmBtu)]]*10^3 -> 3.1481296e+11 | U16: =Table1[[#This Row],[Emissions (g CO2)]]/(Table1[[#This Row],[Generation (TWh)]]*10^9) -> 722.07259
A17: société algérienne de production de l'electricité spa | B17: fossil gas: natural gas, fossil liquids: fuel oil | C17: =SUBSTITUTE(Table1[[#This Row],[Fuel]],", ",",") -> fossil gas: natural gas,fossil liquids: fuel oil | D17: fossil gas: natural gas | E17: fossil liquids: fuel oil | H17: gas turbine | I17: 132 | J17: operating | K17: 2014 | L17: N/A | M17: N/A | N17: 35.8678 | O17: 6.025637 | P17: algeria | Q17: =Table1[[#This Row],[Capacity (MW)]]*0.395*8760*10^-6 -> 0.4567464 | R17: {=AVERAGE(VLOOKUP(_xlfn.TEXTSPLIT(Table1[[#This Row],[Fuel (no space after comma)]], ","), FuelList_Final_EF!$A$2:$B$65, 2, FALSE))} -> 65.583341 | S17: =Table1[[#This Row],[Generation (TWh)]]*10^9*VLOOKUP(Table1[[#This Row],[Turbine/Engine Technology]],Technology_HR!$A$2:$B$11,2,FALSE)*10^-6 -> 5028777.9 | T17: =Table1[[#This Row],[Fuel Consumption (mmBtu)]]*Table1[[#This Row],[Emission Factor (kg CO2/ mmBtu)]]*10^3 -> 3.2980405e+11 | U17: =Table1[[#This Row],[Emissions (g CO2)]]/(Table1[[#This Row],[Generation (TWh)]]*10^9) -> 722.07259
A18: société algérienne de production de l'electricité spa | B18: fossil gas: natural gas, fossil liquids: fuel oil | C18: =SUBSTITUTE(Table1[[#This Row],[Fuel]],", ",",") -> fossil gas: natural gas,fossil liquids: fuel oil | D18: fossil gas: natural gas | E18: fossil liquids: fuel oil | H18: gas turbine | I18: 132 | J18: operating | K18: 2014 | L18: N/A | M18: N/A | N18: 35.8678 | O18: 6.025637 | P18: algeria | Q18: =Table1[[#This Row],[Capacity (MW)]]*0.395*8760*10^-6 -> 0.4567464 | R18: {=AVERAGE(VLOOKUP(_xlfn.TEXTSPLIT(Table1[[#This Row],[Fuel (no space after comma)]], ","), FuelList_Final_EF!$A$2:$B$65, 2, FALSE))} -> 65.583341 | S18: =Table1[[#This Row],[Generation (TWh)]]*10^9*VLOOKUP(Table1[[#This Row],[Turbine/Engine Technology]],Technology_HR!$A$2:$B$11,2,FALSE)*10^-6 -> 5028777.9 | T18: =Table1[[#This Row],[Fuel Consumption (mmBtu)]]*Table1[[#This Row],[Emission Factor (kg CO2/ mmBtu)]]*10^3 -> 3.2980405e+11 | U18: =Table1[[#This Row],[Emissions (g CO2)]]/(Table1[[#This Row],[Generation (TWh)]]*10^9) -> 722.07259
A19: société algérienne de production de l'electricité spa | B19: fossil gas: natural gas, fossil liquids: fuel oil | C19: =SUBSTITUTE(Table1[[#This Row],[Fuel]],", ",",") -> fossil gas: natural gas,fossil liquids: fuel oil | D19: fossil gas: natural gas | E19: fossil liquids: fuel oil | H19: gas turbine | I19: 138.8 | J19: operating | K19: 2019 | L19: N/A | M19: N/A | N19: 35.8678 | O19: 6.025637 | P19: algeria | Q19: =Table1[[#This Row],[Capacity (MW)]]*0.395*8760*10^-6 -> 0.48027576 | R19: {=AVERAGE(VLOOKUP(_xlfn.TEXTSPLIT(Table1[[#This Row],[Fuel (no space after comma)]], ","), FuelList_Final_EF!$A$2:$B$65, 2, FALSE))} -> 65.583341 | S19: =Table1[[#This Row],[Generation (TWh)]]*10^9*VLOOKUP(Table1[[#This Row],[Turbine/Engine Technology]],Technology_HR!$A$2:$B$11,2,FALSE)*10^-6 -> 5287836.1 | T19: =Table1[[#This Row],[Fuel Consumption (mmBtu)]]*Table1[[#This Row],[Emission Factor (kg CO2/ mmBtu)]]*10^3 -> 3.4679396e+11 | U19: =Table1[[#This Row],[Emissions (g CO2)]]/(Table1[[#This Row],[Generation (TWh)]]*10^9) -> 722.07259
A20: société algérienne de production de l'electricité spa | B20: fossil gas: natural gas, fossil liquids: fuel oil | C20: =SUBSTITUTE(Table1[[#This Row],[Fuel]],", ",",") -> fossil gas: natural gas,fossil liquids: fuel oil | D20: fossil gas: natural gas | E20: fossil liquids: fuel oil | H20: gas turbine | I20: 138.8 | J20: operating | K20: 2019 | L20: N/A | M20: N/A | N20: 35.8678 | O20: 6.025637 | P20: algeria | Q20: =Table1[[#This Row],[Capacity (MW)]]*0.395*8760*10^-6 -> 0.48027576 | R20: {=AVERAGE(VLOOKUP(_xlfn.TEXTSPLIT(Table1[[#This Row],[Fuel (no space after comma)]], ","), FuelList_Final_EF!$A$2:$B$65, 2, FALSE))} -> 65.583341 | S20: =Table1[[#This Row],[Generation (TWh)]]*10^9*VLOOKUP(Table1[[#This Row],[Turbine/Engine Technology]],Technology_HR!$A$2:$B$11,2,FALSE)*10^-6 -> 5287836.1 | T20: =Table1[[#This Row],[Fuel Consumption (mmBtu)]]*Table1[[#This Row],[Emission Factor (kg CO2/ mmBtu)]]*10^3 -> 3.4679396e+11 | U20: =Table1[[#This Row],[Emissions (g CO2)]]/(Table1[[#This Row],[Generation (TWh)]]*10^9) -> 722.07259
A21: société algérienne de production de l'electricité spa | B21: fossil gas: natural gas | C21: =SUBSTITUTE(Table1[[#This Row],[Fuel]],", ",",") -> fossil gas: natural gas | D21: fossil gas: natural gas | H21: combined cycle | I21: 699 | J21: operating | K21: 2022 | L21: N/A | M21: N/A | N21: 36.739578 | O21: 6.251014 | P21: algeria | Q21: =Table1[[#This Row],[Capacity (MW)]]*0.395*8760*10^-6 -> 2.4186798 | R21: {=AVERAGE(VLOOKUP(_xlfn.TEXTSPLIT(Table1[[#This Row],[Fuel (no space after comma)]], ","), FuelList_Final_EF!$A$2:$B$65, 2, FALSE))} -> 53.06 | S21: =Table1[[#This Row],[Generation (TWh)]]*10^9*VLOOKUP(Table1[[#This Row],[Turbine/Engine Technology]],Technology_HR!$A$2:$B$11,2,FALSE)*10^-6 -> 18258614 | T21: =Table1[[#This Row],[Fuel Consumption (mmBtu)]]*Table1[[#This Row],[Emission Factor (kg CO2/ mmBtu)]]*10^3 -> 9.6880205e+11 | U21: =Table1[[#This Row],[Emissions (g CO2)]]/(Table1[[#This Row],[Generation (TWh)]]*10^9) -> 400.54994
A22: société algérienne de production de l'electricité spa | B22: fossil gas: natural gas | C22: =SUBSTITUTE(Table1[[#This Row],[Fuel]],", ",",") -> fossil gas: natural gas | D22: fossil gas: natural gas | H22: combined cycle | I22: 699 | J22: operating | K22: 2022 | L22: N/A | M22: N/A | N22: 36.739578 | O22: 6.251014 | P22: algeria | Q22: =Table1[[#This Row],[Capacity (MW)]]*0.395*8760*10^-6 -> 2.4186798 | R22: {=AVERAGE(VLOOKUP(_xlfn.TEXTSPLIT(Table1[[#This Row],[Fuel (no space after comma)]], ","), FuelList_Final_EF!$A$2:$B$65, 2, FALSE))} -> 53.06 | S22: =Table1[[#This Row],[Generation (TWh)]]*10^9*VLOOKUP(Table1[[#This Row],[Turbine/Engine Technology]],Technology_HR!$A$2:$B$11,2,FALSE)*10^-6 -> 18258614 | T22: =Table1[[#This Row],[Fuel Consumption (mmBtu)]]*Table1[[#This Row],[Emission Factor (kg CO2/ mmBtu)]]*10^3 -> 9.6880205e+11 | U22: =Table1[[#This Row],[Emissions (g CO2)]]/(Table1[[#This Row],[Generation (TWh)]]*10^9) -> 400.54994
A23: shariket kahraba berrouaghia spa | B23: fossil gas: natural gas, fossil liquids: fuel oil | C23: =SUBSTITUTE(Table1[[#This Row],[Fuel]],", ",",") -> fossil gas: natural gas,fossil liquids: fuel oil | D23: fossil gas: natural gas | E23: fossil liquids: fuel oil | H23: gas turbine | I23: 244.5 | J23: operating | K23: 2007 | L23: N/A | M23: N/A | N23: 36.140101 | O23: 2.93022 | P23: algeria | Q23: =Table1[[#This Row],[Capacity (MW)]]*0.395*8760*10^-6 -> 0.8460189 | R23: {=AVERAGE(VLOOKUP(_xlfn.TEXTSPLIT(Table1[[#This Row],[Fuel (no space after comma)]], ","), FuelList_Final_EF!$A$2:$B$65, 2, FALSE))} -> 65.583341 | S23: =Table1[[#This Row],[Generation (TWh)]]*10^9*VLOOKUP(Table1[[#This Row],[Turbine/Engine Technology]],Technology_HR!$A$2:$B$11,2,FALSE)*10^-6 -> 9314668.1 | T23: =Table1[[#This Row],[Fuel Consumption (mmBtu)]]*Table1[[#This Row],[Emission Factor (kg CO2/ mmBtu)]]*10^3 -> 6.1088705e+11 | U23: =Table1[[#This Row],[Emissions (g CO2)]]/(Table1[[#This Row],[Generation (TWh)]]*10^9) -> 722.07259
A24: shariket kahraba berrouaghia spa | B24: fossil gas: natural gas, fossil liquids: fuel oil | C24: =SUBSTITUTE(Table1[[#This Row],[Fuel]],", ",",") -> fossil gas: natural gas,fossil liquids: fuel oil | D24: fossil gas: natural gas | E24: fossil liquids: fuel oil | H24: gas turbine | I24: 244.5 | J24: operating | K24: 2007 | L24: N/A | M24: N/A | N24: 36.140101 | O24: 2.93022 | P24: algeria | Q24: =Table1[[#This Row],[Capacity (MW)]]*0.395*8760*10^-6 -> 0.8460189 | R24: {=AVERAGE(VLOOKUP(_xlfn.TEXTSPLIT(Table1[[#This Row],[Fuel (no space after comma)]], ","), FuelList_Final_EF!$A$2:$B$65, 2, FALSE))} -> 65.583341 | S24: =Table1[[#This Row],[Generation (TWh)]]*10^9*VLOOKUP(Table1[[#This Row],[Turbine/Engine Technology]],Technology_HR!$A$2:$B$11,2,FALSE)*10^-6 -> 9314668.1 | T24: =Table1[[#This Row],[Fuel Consumption (mmBtu)]]*Table1[[#This Row],[Emission Factor (kg CO2/ mmBtu)]]*10^3 -> 6.1088705e+11 | U24: =Table1[[#This Row],[Emissions (g CO2)]]/(Table1[[#This Row],[Generation (TWh)]]*10^9) -> 722.07259
A25: société algérienne de production de l'electricité spa | B25: fossil gas: natural gas, fossil liquids: fuel oil | C25: =SUBSTITUTE(Table1[[#This Row],[Fuel]],", ",",") -> fossil gas: natural gas,fossil liquids: fuel oil | D25: fossil gas: natural gas | E25: fossil liquids: fuel oil | H25: gas turbine | I25: 250 | J25: operating | K25: 2016 | L25: N/A | M25: N/A | N25: 36.596922 | O25: 2.878541 | P25: algeria | Q25: =Table1[[#This Row],[Capacity (MW)]]*0.395*8760*10^-6 -> 0.86505 | R25: {=AVERAGE(VLOOKUP(_xlfn.TEXTSPLIT(Table1[[#This Row],[Fuel (no space after comma)]], ","), FuelList_Final_EF!$A$2:$B$65, 2, FALSE))} -> 65.583341 | S25: =Table1[[#This Row],[Generation (TWh)]]*10^9*VLOOKUP(Table1[[#This Row],[Turbine/Engine Technology]],Technology_HR!$A$2:$B$11,2,FALSE)*10^-6 -> 9524200.5 | T25: =Table1[[#This Row],[Fuel Consumption (mmBtu)]]*Table1[[#This Row],[Emission Factor (kg CO2/ mmBtu)]]*10^3 -> 6.2462889e+11 | U25: =Table1[[#This Row],[Emissions (g CO2)]]/(Table1[[#This Row],[Generation (TWh)]]*10^9) -> 722.07259
A26: société algérienne de production de l'electricité spa | B26: fossil gas: natural gas, fossil liquids: fuel oil | C26: =SUBSTITUTE(Table1[[#This Row],[Fuel]],", ",",") -> fossil gas: natural gas,fossil liquids: fuel oil | D26: fossil gas: natural gas | E26: fossil liquids: fuel oil | H26: gas turbine | I26: 250 | J26: operating | K26: 2016 | L26: N/A | M26: N/A | N26: 36.596922 | O26: 2.878541 | P26: algeria | Q26: =Table1[[#This Row],[Capacity (MW)]]*0.395*8760*10^-6 -> 0.86505 | R26: {=AVERAGE(VLOOKUP(_xlfn.TEXTSPLIT(Table1[[#This Row],[Fuel (no space after comma)]], ","), FuelList_Final_EF!$A$2:$B$65, 2, FALSE))} -> 65.583341 | S26: =Table1[[#This Row],[Generation (TWh)]]*10^9*VLOOKUP(Table1[[#This Row],[Turbine/Engine Technology]],Technology_HR!$A$2:$B$11,2,FALSE)*10^-6 -> 9524200.5 | T26: =Table1[[#This Row],[Fuel Consumption (mmBtu)]]*Table1[[#This Row],[Emission Factor (kg CO2/ mmBtu)]]*10^3 -> 6.2462889e+11 | U26: =Table1[[#This Row],[Emissions (g CO2)]]/(Table1[[#This Row],[Generation (TWh)]]*10^9) -> 722.07259
A27: société algérienne de production de l'electricité spa | B27: fossil gas: natural gas, fossil liquids: fuel oil | C27: =SUBSTITUTE(Table1[[#This Row],[Fuel]],", ",",") -> fossil gas: natural gas,fossil liquids: fuel oil | D27: fossil gas: natural gas | E27: fossil liquids: fuel oil | H27: gas turbine | I27: 250 | J27: operating | K27: 2016 | L27: N/A | M27: N/A | N27: 36.596922 | O27: 2.878541 | P27: algeria | Q27: =Table1[[#This Row],[Capacity (MW)]]*0.395*8760*10^-6 -> 0.86505 | R27: {=AVERAGE(VLOOKUP(_xlfn.TEXTSPLIT(Table1[[#This Row],[Fuel (no space after comma)]], ","), FuelList_Final_EF!$A$2:$B$65, 2, FALSE))} -> 65.583341 | S27: =Table1[[#This Row],[Generation (TWh)]]*10^9*VLOOKUP(Table1[[#This Row],[Turbine/Engine Technology]],Technology_HR!$A$2:$B$11,2,FALSE)*10^-6 -> 9524200.5 | T27: =Table1[[#This Row],[Fuel Consumption (mmBtu)]]*Table1[[#This Row],[Emission Factor (kg CO2/ mmBtu)]]*10^3 -> 6.2462889e+11 | U27: =Table1[[#This Row],[Emissions (g CO2)]]/(Table1[[#This Row],[Generation (TWh)]]*10^9) -> 722.07259
A28: société algérienne de production de l'electricité spa | B28: fossil gas: natural gas | C28: =SUBSTITUTE(Table1[[#This Row],[Fuel]],", ",",") -> fossil gas: natural gas | D28: fossil gas: natural gas | H28: gas turbine | I28: 225 | J28: operating | K28: 2019 | L28: N/A | M28: N/A | N28: 35.5658 | O28: -0.9386 | P28: algeria | Q28: =Table1[[#This Row],[Capacity (MW)]]*0.395*8760*10^-6 -> 0.778545 | R28: {=AVERAGE(VLOOKUP(_xlfn.TEXTSPLIT(Table1[[#This Row],[Fuel (no space after comma)]], ","), FuelList_Final_EF!$A$2:$B$65, 2, FALSE))} -> 53.06 | S28: =Table1[[#This Row],[Generation (TWh)]]*10^9*VLOOKUP(Table1[[#This Row],[Turbine/Engine Technology]],Technology_HR!$A$2:$B$11,2,FALSE)*10^-6 -> 8571780.4 | T28: =Table1[[#This Row],[Fuel Consumption (mmBtu)]]*Table1[[#This Row],[Emission Factor (kg CO2/ mmBtu)]]*10^3 -> 454818670677 | U28: =Table1[[#This Row],[Emissions (g CO2)]]/(Table1[[#This Row],[Generation (TWh)]]*10^9) -> 584.1906
A29: société algérienne de production de l'electricité spa | B29: fossil gas: natural gas | C29: =SUBSTITUTE(Table1[[#This Row],[Fuel]],", ",",") -> fossil gas: natural gas | D29: fossil gas: natural gas | H29: gas turbine | I29: 225 | J29: operating | K29: 2020 | L29: N/A | M29: N/A | N29: 35.5658 | O29: -0.9386 | P29: algeria | Q29: =Table1[[#This Row],[Capacity (MW)]]*0.395*8760*10^-6 -> 0.778545 | R29: {=AVERAGE(VLOOKUP(_xlfn.TEXTSPLIT(Table1[[#This Row],[Fuel (no space after comma)]], ","), FuelList_Final_EF!$A$2:$B$65, 2, FALSE))} -> 53.06 | S29: =Table1[[#This Row],[Generation (TWh)]]*10^9*VLOOKUP(Table1[[#This Row],[Turbine/Engine Technology]],Technology_HR!$A$2:$B$11,2,FALSE)*10^-6 -> 8571780.4 | T29: =Table1[[#This Row],[Fuel Consumption (mmBtu)]]*Table1[[#This Row],[Emission Factor (kg CO2/ mmBtu)]]*10^3 -> 454818670677 | U29: =Table1[[#This Row],[Emissions (g CO2)]]/(Table1[[#This Row],[Generation (TWh)]]*10^9) -> 584.1906
A30: société algérienne de production de l'electricité spa | B30: fossil gas: natural gas, fossil liquids: fuel oil | C30: =SUBSTITUTE(Table1[[#This Row],[Fuel]],", ",",") -> fossil gas: natural gas,fossil liquids: fuel oil | D30: fossil gas: natural gas | E30: fossil liquids: fuel oil | H30: combined cycle | I30: 600 | J30: pre-construction | K30: N/A | L30: N/A | M30: N/A | N30: 35.439261 | O30: 2.96076 | P30: algeria | Q30: =Table1[[#This Row],[Capacity (MW)]]*0.395*8760*10^-6 -> 2.07612 | R30: {=AVERAGE(VLOOKUP(_xlfn.TEXTSPLIT(Table1[[#This Row],[Fuel (no space after comma)]], ","), FuelList_Final_EF!$A$2:$B$65, 2, FALSE))} -> 65.583341 | S30: =Table1[[#This Row],[Generation (TWh)]]*10^9*VLOOKUP(Table1[[#This Row],[Turbine/Engine Technology]],Technology_HR!$A$2:$B$11,2,FALSE)*10^-6 -> 15672630 | T30: =Table1[[#This Row],[Fuel Consumption (mmBtu)]]*Table1[[#This Row],[Emission Factor (kg CO2/ mmBtu)]]*10^3 -> 1.0278634e+12 | U30: =Table1[[#This Row],[Emissions (g CO2)]]/(Table1[[#This Row],[Generation (TWh)]]*10^9) -> 495.08864
A31: société algérienne de production de l'electricité spa | B31: fossil gas: natural gas, fossil liquids: fuel oil | C31: =SUBSTITUTE(Table1[[#This Row],[Fuel]],", ",",") -> fossil gas: natural gas,fossil liquids: fuel oil | D31: fossil gas: natural gas | E31: fossil liquids: fuel oil | H31: combined cycle | I31: 600 | J31: pre-construction | K31: N/A | L31: N/A | M31: N/A | N31: 35.439261 | O31: 2.96076 | P31: algeria | Q31: =Table1[[#This Row],[Capacity (MW)]]*0.395*8760*10^-6 -> 2.07612 | R31: {=AVERAGE(VLOOKUP(_xlfn.TEXTSPLIT(Table1[[#This Row],[Fuel (no space after comma)]], ","), FuelList_Final_EF!$A$2:$B$65, 2, FALSE))} -> 65.583341 | S31: =Table1[[#This Row],[Generation (TWh)]]*10^9*VLOOKUP(Table1[[#This Row],[Turbine/Engine Technology]],Technology_HR!$A$2:$B$11,2,FALSE)*10^-6 -> 15672630 | T31: =Table1[[#This Row],[Fuel Consumption (mmBtu)]]*Table1[[#This Row],[Emission Factor (kg CO2/ mmBtu)]]*10^3 -> 1.0278634e+12 | U31: =Table1[[#This Row],[Emissions (g CO2)]]/(Table1[[#This Row],[Generation (TWh)]]*10^9) -> 495.08864
A32: sonelgaz spa | B32: fossil gas: natural gas | C32: =SUBSTITUTE(Table1[[#This Row],[Fuel]],", ",",") -> fossil gas: natural gas | D32: fossil gas: natural gas | H32: gas turbine | I32: 80 | J32: construction | K32: N/A | L32: N/A | M32: N/A | N32: 27.183923 | O32: 2.435821 | P32: algeria | Q32: =Table1[[#This Row],[Capacity (MW)]]*0.395*8760*10^-6 -> 0.276816 | R32: {=AVERAGE(VLOOKUP(_xlfn.TEXTSPLIT(Table1[[#This Row],[Fuel (no space after comma)]], ","), FuelList_Final_EF!$A$2:$B$65, 2, FALSE))} -> 53.06 | S32: =Table1[[#This Row],[Generation (TWh)]]*10^9*VLOOKUP(Table1[[#This Row],[Turbine/Engine Technology]],Technology_HR!$A$2:$B$11,2,FALSE)*10^-6 -> 3047744.2 | T32: =Table1[[#This Row],[Fuel Consumption (mmBtu)]]*Table1[[#This Row],[Emission Factor (kg CO2/ mmBtu)]]*10^3 -> 1.6171331e+11 | U32: =Table1[[#This Row],[Emissions (g CO2)]]/(Table1[[#This Row],[Generation (TWh)]]*10^9) -> 584.1906
A33: sonelgaz spa | B33: fossil gas: natural gas | C33: =SUBSTITUTE(Table1[[#This Row],[Fuel]],", ",",") -> fossil gas: natural gas | D33: fossil gas: natural gas | H33: gas turbine | I33: 80 | J33: construction | K33: N/A | L33: N/A | M33: N/A | N33: 27.183923 | O33: 2.435821 | P33: algeria | Q33: =Table1[[#This Row],[Capacity (MW)]]*0.395*8760*10^-6 -> 0.276816 | R33: {=AVERAGE(VLOOKUP(_xlfn.TEXTSPLIT(Table1[[#This Row],[Fuel (no space after comma)]], ","), FuelList_Final_EF!$A$2:$B$65, 2, FALSE))} -> 53.06 | S33: =Table1[[#This Row],[Generation (TWh)]]*10^9*VLOOKUP(Table1[[#This Row],[Turbine/Engine Technology]],Technology_HR!$A$2:$B$11,2,FALSE)*10^-6 -> 3047744.2 | T33: =Table1[[#This Row],[Fuel Consumption (mmBtu)]]*Table1[[#This Row],[Emission Factor (kg CO2/ mmBtu)]]*10^3 -> 1.6171331e+11 | U33: =Table1[[#This Row],[Emissions (g CO2)]]/(Table1[[#This Row],[Generation (TWh)]]*10^9) -> 584.1906
A34: société algérienne de production de l'electricité spa | B34: fossil gas: natural gas, fossil liquids: fuel oil | C34: =SUBSTITUTE(Table1[[#This Row],[Fuel]],", ",",") -> fossil gas: natural gas,fossil liquids: fuel oil | D34: fossil gas: natural gas | E34: fossil liquids: fuel oil | H34: gas turbine | I34: 146 | J34: operating | K34: 2004 | L34: N/A | M34: N/A | N34: 35.7666 | O34: 7.3619 | P34: algeria | Q34: =Table1[[#This Row],[Capacity (MW)]]*0.395*8760*10^-6 -> 0.5051892 | R34: {=AVERAGE(VLOOKUP(_xlfn.TEXTSPLIT(Table1[[#This Row],[Fuel (no space after comma)]], ","), FuelList_Final_EF!$A$2:$B$65, 2, FALSE))} -> 65.583341 | S34: =Table1[[#This Row],[Generation (TWh)]]*10^9*VLOOKUP(Table1[[#This Row],[Turbine/Engine Technology]],Technology_HR!$A$2:$B$11,2,FALSE)*10^-6 -> 5562133.1 | T34: =Table1[[#This Row],[Fuel Consumption (mmBtu)]]*Table1[[#This Row],[Emission Factor (kg CO2/ mmBtu)]]*10^3 -> 3.6478327e+11 | U34: =Table1[[#This Row],[Emissions (g CO2)]]/(Table1[[#This Row],[Generation (TWh)]]*10^9) -> 722.07259
A35: société algérienne de production de l'electricité spa | B35: fossil gas: natural gas, fossil liquids: fuel oil | C35: =SUBSTITUTE(Table1[[#This Row],[Fuel]],", ",",") -> fossil gas: natural gas,fossil liquids: fuel oil | D35: fossil gas: natural gas | E35: fossil liquids: fuel oil | H35: gas turbine | I35: 146 | J35: operating | K35: 2004 | L35: N/A | M35: N/A | N35: 35.7666 | O35: 7.3619 | P35: algeria | Q35: =Table1[[#This Row],[Capacity (MW)]]*0.395*8760*10^-6 -> 0.5051892 | R35: {=AVERAGE(VLOOKUP(_xlfn.TEXTSPLIT(Table1[[#This Row],[Fuel (no space after comma)]], ","), FuelList_Final_EF!$A$2:$B$65, 2, FALSE))} -> 65.583341 | S35: =Table1[[#This Row],[Generation (TWh)]]*10^9*VLOOKUP(Table1[[#This Row],[Turbine/Engine Technology]],Technology_HR!$A$2:$B$11,2,FALSE)*10^-6 -> 5562133.1 | T35: =Table1[[#This Row],[Fuel Consumption (mmBtu)]]*Table1[[#This Row],[Emission Factor (kg CO2/ mmBtu)]]*10^3 -> 3.6478327e+11 | U35: =Table1[[#This Row],[Emissions (g CO2)]]/(Table1[[#This Row],[Generation (TWh)]]*10^9) -> 722.07259
A36: sharikat kahraba hadjret en nouss spa | B36: fossil gas: natural gas, fossil liquids: fuel oil | C36: =SUBSTITUTE(Table1[[#This Row],[Fuel]],", ",",") -> fossil gas: natural gas,fossil liquids: fuel oil | D36: fossil gas: natural gas | E36: fossil liquids: fuel oil | H36: combined cycle | I36: 409 | J36: operating | K36: 2009 | L36: N/A | M36: N/A | N36: 36.5767 | O36: 2.0797 | P36: algeria | Q36: =Table1[[#This Row],[Capacity (MW)]]*0.395*8760*10^-6 -> 1.4152218 | R36: {=AVERAGE(VLOOKUP(_xlfn.TEXTSPLIT(Table1[[#This Row],[Fuel (no space after comma)]], ","), FuelList_Final_EF!$A$2:$B$65, 2, FALSE))} -> 65.583341 | S36: =Table1[[#This Row],[Generation (TWh)]]*10^9*VLOOKUP(Table1[[#This Row],[Turbine/Engine Technology]],Technology_HR!$A$2:$B$11,2,FALSE)*10^-6 -> 10683509 | T36: =Table1[[#This Row],[Fuel Consumption (mmBtu)]]*Table1[[#This Row],[Emission Factor (kg CO2/ mmBtu)]]*10^3 -> 7.0066024e+11 | U36: =Table1[[#This Row],[Emissions (g CO2)]]/(Table1[[#This Row],[Generation (TWh)]]*10^9) -> 495.08864
A37: sharikat kahraba hadjret en nouss spa | B37: fossil gas: natural gas, fossil liquids: fuel oil | C37: =SUBSTITUTE(Table1[[#This Row],[Fuel]],", ",",") -> fossil gas: natural gas,fossil liquids: fuel oil | D37: fossil gas: natural gas | E37: fossil liquids: fuel oil | H37: combined cycle | I37: 409 | J37: operating | K37: 2009 | L37: N/A | M37: N/A | N37: 36.5767 | O37: 2.0797 | P37: algeria | Q37: =Table1[[#This Row],[Capacity (MW)]]*0.395*8760*10^-6 -> 1.4152218 | R37: {=AVERAGE(VLOOKUP(_xlfn.TEXTSPLIT(Table1[[#This Row],[Fuel (no space after comma)]], ","), FuelList_Final_EF!$A$2:$B$65, 2, FALSE))} -> 65.583341 | S37: =Table1[[#This Row],[Generation (TWh)]]*10^9*VLOOKUP(Table1[[#This Row],[Turbine/Engine Technology]],Technology_HR!$A$2:$B$11,2,FALSE)*10^-6 -> 10683509 | T37: =Table1[[#This Row],[Fuel Consumption (mmBtu)]]*Table1[[#This Row],[Emission Factor (kg CO2/ mmBtu)]]*10^3 -> 7.0066024e+11 | U37: =Table1[[#This Row],[Emissions (g CO2)]]/(Table1[[#This Row],[Generation (TWh)]]*10^9) -> 495.08864
A38: sharikat kahraba hadjret en nouss spa | B38: fossil gas: natural gas, fossil liquids: fuel oil | C38: =SUBSTITUTE(Table1[[#This Row],[Fuel]],", ",",") -> fossil gas: natural gas,fossil liquids: fuel oil | D38: fossil gas: natural gas | E38: fossil liquids: fuel oil | H38: combined cycle | I38: 409 | J38: operating | K38: 2009 | L38: N/A | M38: N/A | N38: 36.5767 | O38: 2.0797 | P38: algeria | Q38: =Table1[[#This Row],[Capacity (MW)]]*0.395*8760*10^-6 -> 1.4152218 | R38: {=AVERAGE(VLOOKUP(_xlfn.TEXTSPLIT(Table1[[#This Row],[Fuel (no space after comma)]], ","), FuelList_Final_EF!$A$2:$B$65, 2, FALSE))} -> 65.583341 | S38: =Table1[[#This Row],[Generation (TWh)]]*10^9*VLOOKUP(Table1[[#This Row],[Turbine/Engine Technology]],Technology_HR!$A$2:$B$11,2,FALSE)*10^-6 -> 10683509 | T38: =Table1[[#This Row],[Fuel Consumption (mmBtu)]]*Table1[[#This Row],[Emission Factor (kg CO2/ mmBtu)]]*10^3 -> 7.0066024e+11 | U38: =Table1[[#This Row],[Emissions (g CO2)]]/(Table1[[#This Row],[Generation (TWh)]]*10^9) -> 495.08864
A39: société algérienne de production de l'electricité spa | B39: fossil gas: natural gas, fossil liquids: fuel oil | C39: =SUBSTITUTE(Table1[[#This Row],[Fuel]],", ",",") -> fossil gas: natural gas,fossil liquids: fuel oil | D39: fossil gas: natural gas | E39: fossil liquids: fuel oil | H39: gas turbine | I39: 209 | J39: operating | K39: 2002 | L39: N/A | M39: N/A | N39: 36.7489 | O39: 3.0823 | P39: algeria | Q39: =Table1[[#This Row],[Capacity (MW)]]*0.395*8760*10^-6 -> 0.7231818 | R39: {=AVERAGE(VLOOKUP(_xlfn.TEXTSPLIT(Table1[[#This Row],[Fuel (no space after comma)]], ","), FuelList_Final_EF!$A$2:$B$65, 2, FALSE))} -> 65.583341 | S39: =Table1[[#This Row],[Generation (TWh)]]*10^9*VLOOKUP(Table1[[#This Row],[Turbine/Engine Technology]],Technology_HR!$A$2:$B$11,2,FALSE)*10^-6 -> 7962231.6 | T39: =Table1[[#This Row],[Fuel Consumption (mmBtu)]]*Table1[[#This Row],[Emission Factor (kg CO2/ mmBtu)]]*10^3 -> 5.2218975e+11 | U39: =Table1[[#This Row],[Emissions (g CO2)]]/(Table1[[#This Row],[Generation (TWh)]]*10^9) -> 722.07259
A40: société algérienne de production de l'electricité spa | B40: fossil gas: natural gas, fossil liquids: fuel oil | C40: =SUBSTITUTE(Table1[[#This Row],[Fuel]],", ",",") -> fossil gas: natural gas,fossil liquids: fuel oil | D40: fossil gas: natural gas | E40: fossil liquids: fuel oil | H40: gas turbine | I40: 209 | J40: operating | K40: 2002 | L40: N/A | M40: N/A | N40: 36.7489 | O40: 3.0823 | P40: algeria | Q40: =Table1[[#This Row],[Capacity (MW)]]*0.395*8760*10^-6 -> 0.7231818 | R40: {=AVERAGE(VLOOKUP(_xlfn.TEXTSPLIT(Table1[[#This Row],[Fuel (no space after comma)]], ","), FuelList_Final_EF!$A$2:$B$65, 2, FALSE))} -> 65.583341 | S40: =Table1[[#This Row],[Generation (TWh)]]*10^9*VLOOKUP(Table1[[#This Row],[Turbine/Engine Technology]],Technology_HR!$A$2:$B$11,2,FALSE)*10^-6 -> 7962231.6 | T40: =Table1[[#This Row],[Fuel Consumption (mmBtu)]]*Table1[[#This Row],[Emission Factor (kg CO2/ mmBtu)]]*10^3 -> 5.2218975e+11 | U40: =Table1[[#This Row],[Emissions (g CO2)]]/(Table1[[#This Row],[Generation (TWh)]]*10^9) -> 722.07259
...

Sheet Technology_HR
A1: Technology | B1: Heat Rate (Btu/ kWh) | C1: Source | D1: Comment
A2: {=_xlfn.UNIQUE(Gas_Oil_Data!H2:H14163)} -> gas turbine | B2: 11010 | C2: https://www.eia.gov/electricity/annual/html/epa_08_02.html
A3: internal combustion | B3: 8900 | C3: https://www.eia.gov/electricity/annual/html/epa_08_02.html
A4: combined cycle | B4: 7549 | C4: https://www.eia.gov/electricity/annual/html/epa_08_02.html
A5: unknown | B5: =AVERAGE(B2:B4,B6:B9,B11) -> 8295.5 | C5: Average of all
A6: ISCC | B6: 7549 | C6: https://www.eia.gov/electricity/annual/html/epa_08_02.html | D6: Combined cycle
A7: steam turbine | B7: 10285 | C7: https://www.eia.gov/electricity/annual/html/epa_08_02.html
A8: ICCC | B8: 7549 | C8: https://www.eia.gov/electricity/annual/html/epa_08_02.html | D8: Combined cycle
A9: AFC | B9: 5973 | C9: https://www.researchgate.net/publication/337168526_Progress_Update_on_the_Allam_Cycle_Commercialization_of_NET_Power_and_the_NET_Power_Demonstration_Facility
A10: N/A | B10: =B5 -> 8295.5 | C10: Average of all
A11: IGCC | B11: 7549 | C11: https://www.eia.gov/electricity/annual/html/epa_08_02.html | D11: Combined cycle

Sheet FuelList_Final_EF
A1: Fuel | B1: Emission Factor (kg CO2/ mmBtu) | C1: Source | D1: Comment
A2: {=_xlfn.UNIQUE(FuelList_IntermediateStep!A2:A111)} -> fossil gas: natural gas | B2: 53.06 | C2: https://www.epa.gov/system/files/documents/2025-01/ghg-emission-factors-hub-2025.pdf
A3: fossil liquids: heavy fuel oil | B3: =77400/948.5 -> 81.60253 | C3: https://www.sciencedirect.com/topics/engineering/specific-emission-factor
A4: fossil gas: lng | B4: =64200/948.5 -> 67.68582 | C4: https://www.ipcc-nggip.iges.or.jp/public/2006gl/pdf/2_Volume2/V2_2_Ch2_Stationary_Combustion.pdf
A5: fossil gas: unknown | B5: =AVERAGE(B2,B4,B7,B10,B47) -> 60.319164 | C5: Average "fossil gas:"
A6: fossil liquids: crude oil | B6: 74.54 | C6: https://www.epa.gov/system/files/documents/2025-01/ghg-emission-factors-hub-2025.pdf
A7: fossil gas: waste heat from natural gas | B7: 66.33 | C7: https://www.epa.gov/system/files/documents/2025-01/ghg-emission-factors-hub-2025.pdf | D7: Steam and Heat
A8: fossil liquids: fuel oil | B8: =266.5/3.412 -> 78.106682 | C8: https://www.volker-quaschning.de/datserv/CO2-spez/index_e.php
A9: fossil liquids: diesel | B9: =266.5/3.412 -> 78.106682 | C9: https://www.volker-quaschning.de/datserv/CO2-spez/index_e.php
A10: fossil gas: coalbed methane | B10: 53.06 | C10: https://www.epa.gov/system/files/documents/2025-01/ghg-emission-factors-hub-2025.pdf | D10: It is a type of natural gas
A11: fossil gas: lng [50%] | B11: =64200/948.5 -> 67.68582 | C11: Lng*(0,5/0,5)
A12: fossil gas: natural gas [95%] | B12: =B2*(0.95/0.5) -> 100.814 | C12: Natural gas*(0,95/05)
A13: other: hydrogen (green) | B13: 0 | C13: https://www.mckinsey.com/industries/automotive-and-assembly/our-insights/how-hydrogen-combustion-engines-can-contribute-to-zero-emissions
A14: fossil gas: natural gas [90%] | B14: =B2*(0.9/0.5) -> 95.508 | C14: Natural gas*(0,9/0,5)
A15: industrial by-product: blast furnace gas | B15: 274.32 | C15: https://www.epa.gov/system/files/documents/2025-01/ghg-emission-factors-hub-2025.pdf
A16: industrial by-product: coke oven gas | B16: 46.85 | C16: https://www.epa.gov/system/files/documents/2025-01/ghg-emission-factors-hub-2025.pdf
A17: fossil liquids: light fuel oil | B17: =74100/948.5 -> 78.123353 | C17: https://www.sciencedirect.com/topics/engineering/specific-emission-factor
A18: industrial by-product: blast furnace gas [90%] | B18: =B15*(0.9/0.5) -> 493.776 | C18: Blast furnace gas*(0,9/0,5)
A19: fossil gas: lng [80%] | B19: =B4*(0.8/0.5) -> 108.29731 | C19: Lng*(0,8/0,5)
A20: fossil liquids: liquefied petroleum gas | B20: 61.71 | C20: https://www.epa.gov/system/files/documents/2025-01/ghg-emission-factors-hub-2025.pdf
A21: fossil gas: natural gas [80%] | B21: =B2*(0.8/0.5) -> 84.896 | C21: Natural gas*(0,8/05)
A22: fossil liquids: naphtha | B22: =73300/948.5 -> 77.279916 | C22: https://www.ipcc-nggip.iges.or.jp/public/2006gl/pdf/2_Volume2/V2_2_Ch2_Stationary_Combustion.pdf
A23: fossil liquids: unknown | B23: =AVERAGE(B3,B6,B8,B9,B17,B20,B22,B26,B27,B31,B50,B62) -> 76.954923 | C23: Average "fossil liquids:"
A24: fossil gas: natural gas [50%] | B24: =B2 -> 53.06 | C24: Natural gas*(0,5/0,5)
A25: other: hydrogen (unknown) | B25: 0 | C25: Average of "other:hydrogen"
A26: fossil liquids: kerosene | B26: 75.2 | C26: https://www.epa.gov/system/files/documents/2025-01/ghg-emission-factors-hub-2025.pdf
A27: fossil liquids: petroleum coke | B27: 102.41 | C27: https://www.epa.gov/system/files/documents/2025-01/ghg-emission-factors-hub-2025.pdf
A28: industrial by-product: blast furnace gas [75%] | B28: =B15*(0.75/0.5) -> 411.48 | C28: Blast furnace gas*(0,75/0,5)
A29: fossil gas: natural gas [70%] | B29: =B2*(0.7/0.5) -> 74.284 | C29: Natural gas*(0,7/0,5)
A30: fossil gas: natural gas [98%] | B30: =B2*(0.98/0.5) -> 103.9976 | C30: Natural gas*(0,98/0,5)
A31: fossil liquids: jet fuel | B31: 72.22 | C31: https://www.epa.gov/system/files/documents/2025-01/ghg-emission-factors-hub-2025.pdf
A32: fossil gas: natural gas [97%] | B32: =B2*(0.97/0.5) -> 102.9364 | C32: Natural gas*(0,97/0,5)
A33: other: other | B33: 0 | C33: Average of "other:"
A34: fossil gas: natural gas [65%] | B34: =B2*(0.65/0.5) -> 68.978 | C34: Natural gas*(0,65/0,5)
A35: 0
A36: coal: unknown | B36: =AVERAGE(B51,B53,B57) -> 100.26357 | C36: Average of "coal:"
A37: other: hydrogen (unknown) [50%] | B37: 0
A38: other: hydrogen (green) [5%] | B38: 0
A39: other: hydrogen (unknown) [10%] | B39: 0
A40: bioenergy: unknown | B40: =AVERAGE(B49,B60,B61,B65) -> 74.0375 | C40: Average of "bioenergy:"
...

Sheet FuelList_IntermediateStep
A1: Fuel: Intermediate Step
A2: {=_xlfn.UNIQUE(Gas_Oil_Data!D2:D14163)} -> fossil gas: natural gas
A3: fossil liquids: heavy fuel oil
A4: fossil gas: lng
A5: fossil gas: unknown
A6: fossil liquids: crude oil
A7: fossil gas: waste heat from natural gas
A8: fossil liquids: fuel oil
A9: fossil liquids: diesel
A10: fossil gas: coalbed methane
A11: fossil gas: lng [50%]
A12: fossil gas: natural gas [95%]
A13: other: hydrogen (green)
A14: fossil gas: natural gas [90%]
... A34: fossil gas: natural gas [65%]
A35: {=_xlfn.UNIQUE(Gas_Oil_Data!E2:E14163)} -> 0
A36: fossil liquids: diesel
A37: fossil liquids: fuel oil
A38: other: other
A39: fossil liquids: light fuel oil
A40: fossil gas: natural gas
A41: coal: unknown
A42: fossil gas: lng
A43: other: hydrogen (unknown) [50%]
A44: other: hydrogen (green) [5%]
A45: fossil liquids: heavy fuel oil
A46: other: hydrogen (unknown) [10%]
A47: industrial by-product: coke oven gas
... A83: other: hydrogen (green) [35%]
A84: {=_xlfn.UNIQUE(Gas_Oil_Data!F2:F14163)} -> 0
A85: fossil liquids: fuel oil
A86: fossil liquids: heavy fuel oil
A87: fossil gas: natural gas
A88: bioenergy: unknown
A89: fossil liquids: diesel
A90: fossil liquids: light fuel oil
A91: fossil gas: lng
A92: other: hydrogen (unknown)
A93: fossil liquids: jet fuel
A94: fossil gas: unknown
...
